Workbook

Sheet Results
A1: manual cat | B1: correct | C1: extent | D1: NER_category | E1: titles | F1: NER | G1: NER_label | H1: desc | I1: method | J1: main_graph | K1: second_graph | L1: third_graph | M1: file_id | N1: entity_start | O1: entity_end
A2: PER | B2: 1 | C2: 1 | D2: 1 | E2: Faster than fear | F2: Ralf | G2: PER | H2: Ralf a pu prouver son innocence et | I2: stanza | M2: 0 | N2: 0 | O2: 4
A3: PER | B3: 0 | C3: 1 | D3: PER | E3: Faster than fear | F3: Sunny | G3: MISC | H3: a pu prouver son innocence et Sunny a été suspendue de ses foncti | I3: stanza | M3: 0 | N3: 35 | O3: 40
E4: Faster than fear | F4: Sunny | G4: PER | H4: a pu prouver son innocence et Sunny a été suspendue de ses foncti | I4: spaCy | M4: 0 | N4: 35 | O4: 40
E5: Faster than fear | F5: affaire Haffner | G5: MISC | H5: e n'a plus rien à voir avec l'affaire Haffner, mais celui-ci demande à ne p | I5: stanza | M5: 0 | N5: 108 | O5: 123
A6: PER | B6: 1 | C6: 1 | D6: 1 | E6: Faster than fear | F6: Haffner | G6: PER | H6: us rien à voir avec l'affaire Haffner, mais celui-ci demande à ne p | I6: spaCy | M6: 0 | N6: 116 | O6: 123
A7: PER | B7: 0 | C7: 1 | D7: PER | E7: Faster than fear | F7: Sunny | G7: LOC | H7: i-ci demande à ne parler qu'à Sunny. D'ailleurs, elle est persuad | I7: spaCy_stanza | M7: 0 | N7: 164 | O7: 169
E8: Faster than fear | F8: Nora | G8: LOC | H8: leurs, elle est persuadée que Nora a divulgué des informations à | I8: spaCy | M8: 0 | N8: 206 | O8: 210
A9: PER | B9: 1 | C9: 1 | D9: 1 | E9: Faster than fear | F9: Nora | G9: PER | H9: leurs, elle est persuadée que Nora a divulgué des informations à | I9: casEN_stanza_priority | J9: grfpersGenerique | M9: 0 | N9: 206 | O9: 210
A10: PER | B10: 1 | C10: 1 | D10: 1 | E10: Faster than fear | F10: Haffner | G10: PER | H10: er à... elle. En garde à vue, Haffner n'avoue toujours pas où se tr | I10: spaCy_stanza | M10: 0 | N10: 311 | O10: 318
A11: PER | B11: 1 | C11: 1 | D11: 1 | E11: Faster than fear | F11: Marcel | G11: PER | H11: oue toujours pas où se trouve Marcel. | I11: casEN_spaCy_stanza | J11: grfpersGenerique | M11: 0 | N11: 353 | O11: 359
A12: PER | B12: 1 | C12: 1 | D12: 1 | E12: Commissaire Magellan (S1-E30) | F12: Tristan Garil | G12: PER | H12: vre du talentueux photographe Tristan Garil s'apprête à être exposée dans | I12: casEN_stanza | J12: grfpersPrenomNom | K12: grftagPrenom | L12: grftagNomFamille | M12: 1 | N12: 35 | O12: 48
E13: Commissaire Magellan (S1-E30) | F13: Tristan | G13: MISC | H13: vre du talentueux photographe Tristan Garil s'apprête à être exposé | I13: spaCy | M13: 1 | N13: 35 | O13: 42
E14: Commissaire Magellan (S1-E30) | F14: galerie | G14: ORG | H14: pprête à être exposée dans la galerie Delandin. Mais la directrice | I14: casEN | J14: grforgProximite | M14: 1 | N14: 82 | O14: 89
A15: PER | B15: 1 | C15: 1 | D15: 1 | E15: Commissaire Magellan (S1-E30) | F15: Delandin | G15: PER | H15: être exposée dans la galerie Delandin. Mais la directrice et fondat | I15: spaCy_stanza_priority | M15: 1 | N15: 90 | O15: 98
E16: Commissaire Magellan (S1-E30) | F16: Delandin | G16: ORG | H16: être exposée dans la galerie Delandin. Mais la directrice et fondat | I16: casEN | J16: grforgSeule | K16: grfpersGenerique | M16: 1 | N16: 90 | O16: 98
A17: PER | B17: 1 | C17: 1 | D17: 1 | E17: Commissaire Magellan (S1-E30) | F17: Estelle Delandin | G17: PER | H17: ctrice et fondatrice du lieu, Estelle Delandin, est assassinée. Le commissai | I17: casEN_spaCy_stanza | J17: grfpersPrenomNom | K17: grftagPrenom | L17: grftagNomFamille | M17: 1 | N17: 142 | O17: 158
E18: Commissaire Magellan (S1-E30) | F18: commissaire Magellan | G18: PER | H18: Delandin, est assassinée. Le commissaire Magellan et le lieutenant Selma Berray | I18: spaCy | M18: 1 | N18: 179 | O18: 199
A19: PER | B19: 1 | C19: 1 | D19: 1 | E19: Commissaire Magellan (S1-E30) | F19: Magellan | G19: PER | H19: st assassinée. Le commissaire Magellan et le lieutenant Selma Berray | I19: casEN_stanza | J19: grfpersContextePersonne | K19: grftagNomFamille | M19: 1 | N19: 191 | O19: 199
A20: PER | B20: 1 | C20: 1 | D20: 1 | E20: Commissaire Magellan (S1-E30) | F20: Selma Berrayah | G20: PER | H20: ire Magellan et le lieutenant Selma Berrayah se chargent de l'enquête. Au | I20: casEN_spaCy_stanza | J20: grfpersPrenomNom | K20: grftagPrenom | L20: grftagNomFamille | M20: 1 | N20: 217 | O20: 231
A21: PER | B21: 0 | C21: 0 | D21: PER | E21: La mort du Père Noël | F21: Le Père Noël | G21: MISC | H21: Le Père Noël est mort. Qui l'a tué ? | I21: spaCy | M21: 3 | N21: 0 | O21: 12
A22: PER | B22: 1 | C22: 1 | D22: 1 | E22: La mort du Père Noël | F22: Père Noël | G22: PER | H22: Le Père Noël est mort. Qui l'a tué ? | I22: casEN_opti | J22: grfpersAmbigus | M22: 3 | N22: 3 | O22: 12
E23: La mort du Père Noël | F23: Père Noël | G23: MISC | H23: Le Père Noël est mort. Qui l'a tué ? | I23: stanza | M23: 3 | N23: 3 | O23: 12
A24: MISC | B24: 1 | C24: 1 | D24: 1 | E24: Commissaire Magellan (S1-E30) | F24: fête de la Bière | G24: MISC | H24: Le jour de la fête de la Bière à Saignac, Christophe Diaz es | I24: stanza | M24: 7 | N24: 14 | O24: 30
E25: Commissaire Magellan (S1-E30) | F25: fête de la | G25: MISC | H25: Le jour de la fête de la Bière à Saignac, Christophe D | I25: spaCy | M25: 7 | N25: 14 | O25: 24
E26: Commissaire Magellan (S1-E30) | F26: Bière | G26: LOC | H26: Le jour de la fête de la Bière à Saignac, Christophe Diaz es | I26: spaCy | M26: 7 | N26: 25 | O26: 30
A27: LOC | B27: 1 | C27: 1 | D27: 1 | E27: Commissaire Magellan (S1-E30) | F27: Saignac | G27: LOC | H27: jour de la fête de la Bière à Saignac, Christophe Diaz est retrouvé | I27: spaCy_stanza | M27: 7 | N27: 33 | O27: 40
A28: PER | B28: 1 | C28: 1 | D28: 1 | E28: Commissaire Magellan (S1-E30) | F28: Christophe Diaz | G28: PER | H28: a fête de la Bière à Saignac, Christophe Diaz est retrouvé mort à la brasse | I28: casEN_spaCy_stanza | J28: grfpersPrenomNom | K28: grftagPrenom | L28: grftagNomFamille | M28: 7 | N28: 42 | O28: 57
E29: Commissaire Magellan (S1-E30) | F29: brasserie | G29: ORG | H29: e Diaz est retrouvé mort à la brasserie des Trois Amis. Le jeune bras | I29: casEN | J29: grforgProximite | M29: 7 | N29: 81 | O29: 90
E30: Commissaire Magellan (S1-E30) | F30: Trois Amis | G30: ORG | H30: rouvé mort à la brasserie des Trois Amis. Le jeune brasseur avait un a | I30: spaCy_stanza | M30: 7 | N30: 95 | O30: 105
A31: PER | B31: 1 | C31: 1 | D31: 1 | E31: Commissaire Magellan (S1-E30) | F31: Magellan | G31: PER | H31: ale. Au cours de son enquête, Magellan découvre... la rivalité qui o | I31: casEN_spaCy_stanza | J31: grfpersGenerique | M31: 7 | N31: 267 | O31: 275
A32: PER | B32: 1 | C32: 1 | D32: 1 | E32: Commissaire Magellan (S1-E30) | F32: Claude Verague | G32: PER | H32: t la victime à son beau-père, Claude Verague, également brasseur. Mais le | I32: casEN_spaCy_stanza | J32: grfpersPrenomNom | K32: grftagPrenom | L32: grftagNomFamille | M32: 7 | N32: 341 | O32: 355
E33: Commissaire Magellan (S1-E34) | F33: commissaire Magellan | G33: PER | H33: Le commissaire Magellan et la lieutenante Berrayah mè | I33: spaCy | M33: 8 | N33: 3 | O33: 23
A34: PER | B34: 1 | C34: 1 | D34: 1 | E34: Commissaire Magellan (S1-E34) | F34: Magellan | G34: PER | H34: Le commissaire Magellan et la lieutenante Berrayah mè | I34: casEN_stanza | J34: grfpersContextePersonne | K34: grftagNomFamille | M34: 8 | N34: 15 | O34: 23
E35: Commissaire Magellan (S1-E34) | F35: Berrayah | G35: MISC | H35: re Magellan et la lieutenante Berrayah mènent des investigations sur | I35: spaCy | M35: 8 | N35: 42 | O35: 50
A36: PER | B36: 1 | C36: 1 | D36: 1 | E36: Commissaire Magellan (S1-E34) | F36: Berrayah | G36: PER | H36: re Magellan et la lieutenante Berrayah mènent des investigations sur | I36: casEN_stanza_priority | J36: grfpersContextePersonne | K36: grftagNomFamille | M36: 8 | N36: 42 | O36: 50
A37: PER | B37: 1 | C37: 1 | D37: 1 | E37: Commissaire Magellan (S1-E34) | F37: Audrey Galvi | G37: PER | H37: stigations sur l'assassinat d'Audrey Galvi, une championne olympique dev | I37: casEN_spaCy_stanza | J37: grfpersPrenomNom | K37: grftagPrenom | L37: grftagNomFamille | M37: 8 | N37: 96 | O37: 108
A38: PER | B38: 1 | C38: 1 | D38: 1 | E38: Commissaire Magellan (S1-E34) | F38: Lucie Mauricourt | G38: PER | H38: er deux prodiges de la glace, Lucie Mauricourt et Lorena Bardin, jusqu'aux.. | I38: casEN_spaCy_stanza | J38: grfpersPrenomNom | K38: grftagPrenom | L38: grftagNomFamille | M38: 8 | N38: 246 | O38: 262
A39: PER | B39: 1 | C39: 1 | D39: 1 | E39: Commissaire Magellan (S1-E34) | F39: Lorena Bardin | G39: PER | H39: la glace, Lucie Mauricourt et Lorena Bardin, jusqu'aux... marches du podi | I39: casEN_spaCy_stanza | J39: grfpersPrenomNom | K39: grftagPrenom | L39: grftagNomFamille | M39: 8 | N39: 266 | O39: 279
A40: PER | B40: 1 | C40: 1 | D40: 1 | E40: Commissaire Magellan (S1-E34) | F40: Magellan | G40: PER | H40: squ'aux... marches du podium. Magellan s'intéresse de près à ces deu | I40: casEN_spaCy_stanza | J40: grfpersGenerique | M40: 8 | N40: 313 | O40: 321
...

Sheet NER
A1: methods | B1: Total Founds | C1: Corrected | D1: Correct | E1: Accuracy | F1: Time | G1: Choose
A2: stanza | B2: =COUNTIF(Results!I:I, A2) -> 7391 | C2: =COUNTIFS(Results!I:I, A2, Results!B:B, 1) + COUNTIFS(Results!I:I, A2, Results!B:B, 0) -> 1458 | D2: =COUNTIFS(Results!I:I, A2,Results!B:B, 1) -> 1105 | E2: =D2/C2 -> 0.75788752 | F2: 367.36s CPU vs 104.43s GPU (rtx3070 FE) | G2: 0 | J2: Total | K2: Accuracy | L2: Data Gains | M2: Accuracy Loss
A3: spaCy | B3: =COUNTIF(Results!I:I, A3) -> 9476 | C3: =COUNTIFS(Results!I:I, A3, Results!B:B, 1) + COUNTIFS(Results!I:I, A3, Results!B:B, 0) -> 4965 | D3: =COUNTIFS(Results!I:I, A3,Results!B:B, 1) -> 673 | E3: =D3/C3 -> 0.13554884 | F3: 70.65s | G3: 0 | I3: old intersection (spaCy + CasEN) | J3: 5970 | K3: 0.977 | L3: =IFERROR((J3-J3)/J3, 0) -> 0 | M3: =K3-K3 -> 0
A4: spaCy_stanza | B4: =COUNTIF(Results!I:I, A4) -> 5472 | C4: =COUNTIFS(Results!I:I, A4, Results!B:B, 1) + COUNTIFS(Results!I:I, A4, Results!B:B, 0) -> 4537 | D4: =COUNTIFS(Results!I:I, A4,Results!B:B, 1) -> 3241 | E4: =D4/C4 -> 0.71434869 | G4: 0 | I4: spaCy + CasEN + opti + priority | J4: 7990 | K4: 0.95181187 | L4: 0.33835846 | M4: 0.025165797
A5: casEN_stanza_priority | B5: =COUNTIF(Results!I:I, A5) -> 1119 | C5: =COUNTIFS(Results!I:I, A5, Results!B:B, 1) + COUNTIFS(Results!I:I, A5, Results!B:B, 0) -> 650 | D5: =COUNTIFS(Results!I:I, A5,Results!B:B, 1) -> 592 | E5: =D5/C5 -> 0.91076923 | G5: 1 | I5: spaCy_casEN_Stanza | J5: =B6 -> 5523 | K5: =E6 -> 0.99116873 | L5: =IFERROR((J5-J3)/J3, 0) -> -0.074874372 | M5: =K3-K5 -> -0.014168734
A6: casEN_spaCy_stanza | B6: =COUNTIF(Results!I:I, A6) -> 5523 | C6: =COUNTIFS(Results!I:I, A6, Results!B:B, 1) + COUNTIFS(Results!I:I, A6, Results!B:B, 0) -> 5322 | D6: =COUNTIFS(Results!I:I, A6,Results!B:B, 1) -> 5275 | E6: =D6/C6 -> 0.99116873 | G6: 1
A7: casEN_stanza | B7: =COUNTIF(Results!I:I, A7) -> 740 | C7: =COUNTIFS(Results!I:I, A7, Results!B:B, 1) + COUNTIFS(Results!I:I, A7, Results!B:B, 0) -> 544 | D7: =COUNTIFS(Results!I:I, A7,Results!B:B, 1) -> 500 | E7: =D7/C7 -> 0.91911765 | G7: 1
A8: casEN | B8: =COUNTIF(Results!I:I, A8) -> 4976 | C8: =COUNTIFS(Results!I:I, A8, Results!B:B, 1) + COUNTIFS(Results!I:I, A8, Results!B:B, 0) -> 1092 | D8: =COUNTIFS(Results!I:I, A8,Results!B:B, 1) -> 376 | E8: =D8/C8 -> 0.34432234 | G8: 0
A9: spaCy_stanza_priority | B9: =COUNTIF(Results!I:I, A9) -> 71 | C9: =COUNTIFS(Results!I:I, A9, Results!B:B, 1) + COUNTIFS(Results!I:I, A9, Results!B:B, 0) -> 57 | D9: =COUNTIFS(Results!I:I, A9,Results!B:B, 1) -> 54 | E9: =D9/C9 -> 0.94736842 | G9: 1
A10: casEN_opti | B10: =COUNTIF(Results!I:I, A10) -> 505 | C10: =COUNTIFS(Results!I:I, A10, Results!B:B, 1) + COUNTIFS(Results!I:I, A10, Results!B:B, 0) -> 378 | D10: =COUNTIFS(Results!I:I, A10,Results!B:B, 1) -> 340 | E10: =D10/C10 -> 0.8994709 | G10: 1 | J10: Total Founds | K10: Corrected | L10: Correct | M10: Accuracy | N10: Data Gains | O10: Accuracy Loss
A11: casEN_spaCy | B11: =COUNTIF(Results!I:I, A11) -> 260 | C11: =COUNTIFS(Results!I:I, A11, Results!B:B, 1) + COUNTIFS(Results!I:I, A11, Results!B:B, 0) -> 236 | D11: =COUNTIFS(Results!I:I, A11,Results!B:B, 1) -> 179 | E11: =D11/C11 -> 0.75847458 | G11: 0 | I11: VS OLD inter | J11: =SUMIF(G2:G12, 1, B2:B12) -> 7958 | K11: =SUMIF(G2:G12, 1, C2:C12) -> 6951 | L11: =SUMIF(G2:G12, 1, D2:D12) -> 6761 | M11: =IFERROR(L11/K11, 0) -> 0.9726658 | N11: =(J11-J3)/J3 -> 0.33299832 | O11: =K3-M11 -> 0.0043341965
A12: casEN_spaCy_priority | B12: =COUNTIF(Results!I:I, A12) -> 110 | C12: =COUNTIFS(Results!I:I, A12, Results!B:B, 1) + COUNTIFS(Results!I:I, A12, Results!B:B, 0) -> 102 | D12: =COUNTIFS(Results!I:I, A12,Results!B:B, 1) -> 76 | E12: =D12/C12 -> 0.74509804 | G12: 0 | I12: VS spaCy casEN opti priority | J12: =SUMIF(G3:G13, 1, B3:B13) -> 7958 | K12: =SUMIF(G3:G13, 1, C3:C13) -> 6951 | L12: =SUMIF(G3:G13, 1, D3:D13) -> 6761 | M12: =IFERROR(L12/K12, 0) -> 0.9726658 | N12: =(J12-J4)/J4 -> -0.0040050063 | O12: =K4-M12 -> -0.02085393
I13: PER | J13: =SUMIF(R22:R33, 1, B22:B33) -> 8041 | K13: =SUMIF(R22:R33, 1, C22:C33) -> 5835 | L13: =SUMIF(R22:R33, 1, D22:D33) -> 5456 | M13: =IFERROR(L13/K13, 0) -> 0.93504713
I14: LOC | J14: =SUMIF(R22:R33, 1, F22:F33) -> 2431 | K14: =SUMIF(R22:R33, 1, G22:G33) -> 1447 | L14: =SUMIF(R22:R33, 1, H22:H33) -> 1369 | M14: =IFERROR(L14/K14, 0) -> 0.94609537
A15: Total CasEN | B15: =B5+B6+B7+B8+B10+B11+B12 -> 13233 | C15: =C5+C6+C7+C8+C10+C11+C12 -> 8324 | D15: =D5+D6+D7+D8+D10+D11+D12 -> 7338 | E15: =D15/C15 -> 0.88154733 | I15: ORG | J15: =SUMIF(R22:R33, 1, J22:J33) -> 2391 | K15: =SUMIF(R22:R33, 1, K22:K33) -> 704 | L15: =SUMIF(R22:R33, 1, L22:L33) -> 258 | M15: =IFERROR(L15/K15, 0) -> 0.36647727
A16: Total Stanza | B16: =B2+B4+B5+B6+B7+B9 -> 20316 | C16: =C2+C4+C5+C6+C7+C9 -> 12568 | D16: =D2+D4+D5+D6+D7+D9 -> 10767 | E16: =D16/C16 -> 0.85669955 | I16: MISC | J16: =SUMIF(R22:R33, 1, N22:N33) -> 0 | K16: =SUMIF(R22:R33, 1, O22:O33) -> 0 | L16: =SUMIF(R22:R33, 1, P22:P33) -> 0 | M16: =IFERROR(L16/K16, 0) -> 0
A17: Total SpaCy | B17: =B3+B4+B6+B9+B11+B12 -> 20912 | C17: =C3+C4+C6+C9+C11+C12 -> 15219 | D17: =D3+D4+D6+D9+D11+D12 -> 9498 | E17: =D17/C17 -> 0.62408831
A21: method | B21: PER | C21: Corrected | D21: Correct | E21: Accuracy | F21: LOC | G21: Corrected | H21: Correct | I21: Accuracy | J21: ORG | K21: Corrected | L21: Correct | M21: Accuracy | N21: MISC | O21: Corrected | P21: Correct | Q21: Accuracy | R21: Choose
A22: stanza | B22: =COUNTIFS(Results!$I:$I, A22, Results!$G:$G, $B$21) -> 3079 | C22: =COUNTIFS(Results!$I:$I, A22, Results!$G:$G, $B$21, Results!B:B, 1) + COUNTIFS(Results!$I:$I, A22, Results!$G:$G, $B$21, Results!B:B, 0) -> 847 | D22: =COUNTIFS(Results!$I:$I, A22, Results!$G:$G, $B$21, Results!B:B, 1) -> 825 | E22: =IFERROR(D22/C22, 0) -> 0.97402597 | F22: =COUNTIFS(Results!$I:$I, $A22, Results!$G:$G, $F$21) -> 816 | G22: =COUNTIFS(Results!$I:$I, $A22, Results!$G:$G, $F$21, Results!B:B, 1) + COUNTIFS(Results!$I:$I, $A22, Results!$G:$G, $F$21, Results!B:B, 0) -> 257 | H22: =COUNTIFS(Results!$I:$I, $A22, Results!$G:$G, $F$21, Results!B:B, 1) -> 218 | I22: =IFERROR(H22/G22, 0) -> 0.84824903 | J22: =COUNTIFS(Results!$I:$I, $A22,Results!$G:$G, $J$21) -> 975 | K22: =COUNTIFS(Results!$I:$I, $A22,Results!$G:$G, $J$21, Results!B:B, 1) + COUNTIFS(Results!$I:$I, $A22,Results!$G:$G, $J$21, Results!B:B, 0) -> 91 | L22: =COUNTIFS(Results!$I:$I, $A22,Results!$G:$G, $J$21, Results!B:B, 1) -> 53 | M22: =IFERROR(L22/K22, 0) -> 0.58241758 | N22: =COUNTIFS(Results!$I:$I, $A22, Results!$G:$G, $N$21) -> 2521 | O22: =COUNTIFS(Results!$I:$I, $A22, Results!$G:$G, $N$21, Results!B:B, 1) + COUNTIFS(Results!$I:$I, $A22, Results!$G:$G, $N$21, Results!B:B, 0) -> 263 | P22: =COUNTIFS(Results!$I:$I, $A22, Results!$G:$G, $N$21, Results!B:B, 1) -> 9 | Q22: =IFERROR(P22/O22, 0) -> 0.034220532 | R22: =G2 -> 0
A23: spaCy_stanza | B23: =COUNTIFS(Results!$I:$I, A23, Results!$G:$G, $B$21) -> 2574 | C23: =COUNTIFS(Results!$I:$I, A23, Results!$G:$G, $B$21, Results!B:B, 1) + COUNTIFS(Results!$I:$I, A23, Results!$G:$G, $B$21, Results!B:B, 0) -> 2138 | D23: =COUNTIFS(Results!$I:$I, A23, Results!$G:$G, $B$21, Results!B:B, 1) -> 2057 | E23: =IFERROR(D23/C23, 0) -> 0.96211413 | F23: =COUNTIFS(Results!$I:$I, $A23, Results!$G:$G, $F$21) -> 1222 | G23: =COUNTIFS(Results!$I:$I, $A23, Results!$G:$G, $F$21, Results!B:B, 1) + COUNTIFS(Results!$I:$I, $A23, Results!$G:$G, $F$21, Results!B:B, 0) -> 1084 | H23: =COUNTIFS(Results!$I:$I, $A23, Results!$G:$G, $F$21, Results!B:B, 1) -> 917 | I23: =IFERROR(H23/G23, 0) -> 0.84594096 | J23: =COUNTIFS(Results!$I:$I, $A23,Results!$G:$G, $J$21) -> 246 | K23: =COUNTIFS(Results!$I:$I, $A23,Results!$G:$G, $J$21, Results!B:B, 1) + COUNTIFS(Results!$I:$I, $A23,Results!$G:$G, $J$21, Results!B:B, 0) -> 183 | L23: =COUNTIFS(Results!$I:$I, $A23,Results!$G:$G, $J$21, Results!B:B, 1) -> 149 | M23: =IFERROR(L23/K23, 0) -> 0.81420765 | N23: =COUNTIFS(Results!$I:$I, $A23, Results!$G:$G, $N$21) -> 1430 | O23: =COUNTIFS(Results!$I:$I, $A23, Results!$G:$G, $N$21, Results!B:B, 1) + COUNTIFS(Results!$I:$I, $A23, Results!$G:$G, $N$21, Results!B:B, 0) -> 1132 | P23: =COUNTIFS(Results!$I:$I, $A23, Results!$G:$G, $N$21, Results!B:B, 1) -> 118 | Q23: =IFERROR(P23/O23, 0) -> 0.10424028 | R23: =G3 -> 0
A24: spaCy | B24: =COUNTIFS(Results!$I:$I, A24, Results!$G:$G, $B$21) -> 1713 | C24: =COUNTIFS(Results!$I:$I, A24, Results!$G:$G, $B$21, Results!B:B, 1) + COUNTIFS(Results!$I:$I, A24, Results!$G:$G, $B$21, Results!B:B, 0) -> 906 | D24: =COUNTIFS(Results!$I:$I, A24, Results!$G:$G, $B$21, Results!B:B, 1) -> 415 | E24: =IFERROR(D24/C24, 0) -> 0.4580574 | F24: =COUNTIFS(Results!$I:$I, $A24, Results!$G:$G, $F$21) -> 4108 | G24: =COUNTIFS(Results!$I:$I, $A24, Results!$G:$G, $F$21, Results!B:B, 1) + COUNTIFS(Results!$I:$I, $A24, Results!$G:$G, $F$21, Results!B:B, 0) -> 2349 | H24: =COUNTIFS(Results!$I:$I, $A24, Results!$G:$G, $F$21, Results!B:B, 1) -> 199 | I24: =IFERROR(H24/G24, 0) -> 0.084716901 | J24: =COUNTIFS(Results!$I:$I, $A24,Results!$G:$G, $J$21) -> 648 | K24: =COUNTIFS(Results!$I:$I, $A24,Results!$G:$G, $J$21, Results!B:B, 1) + COUNTIFS(Results!$I:$I, $A24,Results!$G:$G, $J$21, Results!B:B, 0) -> 258 | L24: =COUNTIFS(Results!$I:$I, $A24,Results!$G:$G, $J$21, Results!B:B, 1) -> 45 | M24: =IFERROR(L24/K24, 0) -> 0.1744186 | N24: =COUNTIFS(Results!$I:$I, $A24, Results!$G:$G, $N$21) -> 3007 | O24: =COUNTIFS(Results!$I:$I, $A24, Results!$G:$G, $N$21, Results!B:B, 1) + COUNTIFS(Results!$I:$I, $A24, Results!$G:$G, $N$21, Results!B:B, 0) -> 1452 | P24: =COUNTIFS(Results!$I:$I, $A24, Results!$G:$G, $N$21, Results!B:B, 1) -> 14 | Q24: =IFERROR(P24/O24, 0) -> 0.0096418733 | R24: =G4 -> 0
A25: casEN_stanza_priority | B25: =COUNTIFS(Results!$I:$I, A25, Results!$G:$G, $B$21) -> 1119 | C25: =COUNTIFS(Results!$I:$I, A25, Results!$G:$G, $B$21, Results!B:B, 1) + COUNTIFS(Results!$I:$I, A25, Results!$G:$G, $B$21, Results!B:B, 0) -> 650 | D25: =COUNTIFS(Results!$I:$I, A25, Results!$G:$G, $B$21, Results!B:B, 1) -> 592 | E25: =IFERROR(D25/C25, 0) -> 0.91076923 | F25: =COUNTIFS(Results!$I:$I, $A25, Results!$G:$G, $F$21) -> 0 | G25: =COUNTIFS(Results!$I:$I, $A25, Results!$G:$G, $F$21, Results!B:B, 1) + COUNTIFS(Results!$I:$I, $A25, Results!$G:$G, $F$21, Results!B:B, 0) -> 0 | H25: =COUNTIFS(Results!$I:$I, $A25, Results!$G:$G, $F$21, Results!B:B, 1) -> 0 | I25: =IFERROR(H25/G25, 0) -> 0 | J25: =COUNTIFS(Results!$I:$I, $A25,Results!$G:$G, $J$21) -> 0 | K25: =COUNTIFS(Results!$I:$I, $A25,Results!$G:$G, $J$21, Results!B:B, 1) + COUNTIFS(Results!$I:$I, $A25,Results!$G:$G, $J$21, Results!B:B, 0) -> 0 | L25: =COUNTIFS(Results!$I:$I, $A25,Results!$G:$G, $J$21, Results!B:B, 1) -> 0 | M25: =IFERROR(L25/K25, 0) -> 0 | N25: =COUNTIFS(Results!$I:$I, $A25, Results!$G:$G, $N$21) -> 0 | O25: =COUNTIFS(Results!$I:$I, $A25, Results!$G:$G, $N$21, Results!B:B, 1) + COUNTIFS(Results!$I:$I, $A25, Results!$G:$G, $N$21, Results!B:B, 0) -> 0 | P25: =COUNTIFS(Results!$I:$I, $A25, Results!$G:$G, $N$21, Results!B:B, 1) -> 0 | Q25: =IFERROR(P25/O25, 0) -> 0 | R25: =G5 -> 1
A26: casEN_spaCy_stanza | B26: =COUNTIFS(Results!$I:$I, A26, Results!$G:$G, $B$21) -> 4507 | C26: =COUNTIFS(Results!$I:$I, A26, Results!$G:$G, $B$21, Results!B:B, 1) + COUNTIFS(Results!$I:$I, A26, Results!$G:$G, $B$21, Results!B:B, 0) -> 4309 | D26: =COUNTIFS(Results!$I:$I, A26, Results!$G:$G, $B$21, Results!B:B, 1) -> 4271 | E26: =IFERROR(D26/C26, 0) -> 0.99118125 | F26: =COUNTIFS(Results!$I:$I, $A26, Results!$G:$G, $F$21) -> 930 | G26: =COUNTIFS(Results!$I:$I, $A26, Results!$G:$G, $F$21, Results!B:B, 1) + COUNTIFS(Results!$I:$I, $A26, Results!$G:$G, $F$21, Results!B:B, 0) -> 928 | H26: =COUNTIFS(Results!$I:$I, $A26, Results!$G:$G, $F$21, Results!B:B, 1) -> 924 | I26: =IFERROR(H26/G26, 0) -> 0.99568966 | J26: =COUNTIFS(Results!$I:$I, $A26,Results!$G:$G, $J$21) -> 86 | K26: =COUNTIFS(Results!$I:$I, $A26,Results!$G:$G, $J$21, Results!B:B, 1) + COUNTIFS(Results!$I:$I, $A26,Results!$G:$G, $J$21, Results!B:B, 0) -> 85 | L26: =COUNTIFS(Results!$I:$I, $A26,Results!$G:$G, $J$21, Results!B:B, 1) -> 80 | M26: =IFERROR(L26/K26, 0) -> 0.94117647 | N26: =COUNTIFS(Results!$I:$I, $A26, Results!$G:$G, $N$21) -> 0 | O26: =COUNTIFS(Results!$I:$I, $A26, Results!$G:$G, $N$21, Results!B:B, 1) + COUNTIFS(Results!$I:$I, $A26, Results!$G:$G, $N$21, Results!B:B, 0) -> 0 | P26: =COUNTIFS(Results!$I:$I, $A26, Results!$G:$G, $N$21, Results!B:B, 1) -> 0 | Q26: =IFERROR(P26/O26, 0) -> 0 | R26: =G6 -> 1
A27: casEN_stanza | B27: =COUNTIFS(Results!$I:$I, A27, Results!$G:$G, $B$21) -> 538 | C27: =COUNTIFS(Results!$I:$I, A27, Results!$G:$G, $B$21, Results!B:B, 1) + COUNTIFS(Results!$I:$I, A27, Results!$G:$G, $B$21, Results!B:B, 0) -> 355 | D27: =COUNTIFS(Results!$I:$I, A27, Results!$G:$G, $B$21, Results!B:B, 1) -> 334 | E27: =IFERROR(D27/C27, 0) -> 0.94084507 | F27: =COUNTIFS(Results!$I:$I, $A27, Results!$G:$G, $F$21) -> 144 | G27: =COUNTIFS(Results!$I:$I, $A27, Results!$G:$G, $F$21, Results!B:B, 1) + COUNTIFS(Results!$I:$I, $A27, Results!$G:$G, $F$21, Results!B:B, 0) -> 139 | H27: =COUNTIFS(Results!$I:$I, $A27, Results!$G:$G, $F$21, Results!B:B, 1) -> 139 | I27: =IFERROR(H27/G27, 0) -> 1 | J27: =COUNTIFS(Results!$I:$I, $A27,Results!$G:$G, $J$21) -> 58 | K27: =COUNTIFS(Results!$I:$I, $A27,Results!$G:$G, $J$21, Results!B:B, 1) + COUNTIFS(Results!$I:$I, $A27,Results!$G:$G, $J$21, Results!B:B, 0) -> 50 | L27: =COUNTIFS(Results!$I:$I, $A27,Results!$G:$G, $J$21, Results!B:B, 1) -> 27 | M27: =IFERROR(L27/K27, 0) -> 0.54 | N27: =COUNTIFS(Results!$I:$I, $A27, Results!$G:$G, $N$21) -> 0 | O27: =COUNTIFS(Results!$I:$I, $A27, Results!$G:$G, $N$21, Results!B:B, 1) + COUNTIFS(Results!$I:$I, $A27, Results!$G:$G, $N$21, Results!B:B, 0) -> 0 | P27: =COUNTIFS(Results!$I:$I, $A27, Results!$G:$G, $N$21, Results!B:B, 1) -> 0 | Q27: =IFERROR(P27/O27, 0) -> 0 | R27: =G7 -> 1
A28: spaCy_stanza_priority | B28: =COUNTIFS(Results!$I:$I, A28, Results!$G:$G, $B$21) -> 71 | C28: =COUNTIFS(Results!$I:$I, A28, Results!$G:$G, $B$21, Results!B:B, 1) + COUNTIFS(Results!$I:$I, A28, Results!$G:$G, $B$21, Results!B:B, 0) -> 57 | D28: =COUNTIFS(Results!$I:$I, A28, Results!$G:$G, $B$21, Results!B:B, 1) -> 54 | E28: =IFERROR(D28/C28, 0) -> 0.94736842 | F28: =COUNTIFS(Results!$I:$I, $A28, Results!$G:$G, $F$21) -> 0 | G28: =COUNTIFS(Results!$I:$I, $A28, Results!$G:$G, $F$21, Results!B:B, 1) + COUNTIFS(Results!$I:$I, $A28, Results!$G:$G, $F$21, Results!B:B, 0) -> 0 | H28: =COUNTIFS(Results!$I:$I, $A28, Results!$G:$G, $F$21, Results!B:B, 1) -> 0 | I28: =IFERROR(H28/G28, 0) -> 0 | J28: =COUNTIFS(Results!$I:$I, $A28,Results!$G:$G, $J$21) -> 0 | K28: =COUNTIFS(Results!$I:$I, $A28,Results!$G:$G, $J$21, Results!B:B, 1) + COUNTIFS(Results!$I:$I, $A28,Results!$G:$G, $J$21, Results!B:B, 0) -> 0 | L28: =COUNTIFS(Results!$I:$I, $A28,Results!$G:$G, $J$21, Results!B:B, 1) -> 0 | M28: =IFERROR(L28/K28, 0) -> 0 | N28: =COUNTIFS(Results!$I:$I, $A28, Results!$G:$G, $N$21) -> 0 | O28: =COUNTIFS(Results!$I:$I, $A28, Results!$G:$G, $N$21, Results!B:B, 1) + COUNTIFS(Results!$I:$I, $A28, Results!$G:$G, $N$21, Results!B:B, 0) -> 0 | P28: =COUNTIFS(Results!$I:$I, $A28, Results!$G:$G, $N$21, Results!B:B, 1) -> 0 | Q28: =IFERROR(P28/O28, 0) -> 0 | R28: =G8 -> 0
A29: casEN | B29: =COUNTIFS(Results!$I:$I, A29, Results!$G:$G, $B$21) -> 1725 | C29: =COUNTIFS(Results!$I:$I, A29, Results!$G:$G, $B$21, Results!B:B, 1) + COUNTIFS(Results!$I:$I, A29, Results!$G:$G, $B$21, Results!B:B, 0) -> 460 | D29: =COUNTIFS(Results!$I:$I, A29, Results!$G:$G, $B$21, Results!B:B, 1) -> 211 | E29: =IFERROR(D29/C29, 0) -> 0.45869565 | F29: =COUNTIFS(Results!$I:$I, $A29, Results!$G:$G, $F$21) -> 1089 | G29: =COUNTIFS(Results!$I:$I, $A29, Results!$G:$G, $F$21, Results!B:B, 1) + COUNTIFS(Results!$I:$I, $A29, Results!$G:$G, $F$21, Results!B:B, 0) -> 134 | H29: =COUNTIFS(Results!$I:$I, $A29, Results!$G:$G, $F$21, Results!B:B, 1) -> 78 | I29: =IFERROR(H29/G29, 0) -> 0.58208955 | J29: =COUNTIFS(Results!$I:$I, $A29,Results!$G:$G, $J$21) -> 2162 | K29: =COUNTIFS(Results!$I:$I, $A29,Results!$G:$G, $J$21, Results!B:B, 1) + COUNTIFS(Results!$I:$I, $A29,Results!$G:$G, $J$21, Results!B:B, 0) -> 498 | L29: =COUNTIFS(Results!$I:$I, $A29,Results!$G:$G, $J$21, Results!B:B, 1) -> 87 | M29: =IFERROR(L29/K29, 0) -> 0.1746988 | N29: =COUNTIFS(Results!$I:$I, $A29, Results!$G:$G, $N$21) -> 0 | O29: =COUNTIFS(Results!$I:$I, $A29, Results!$G:$G, $N$21, Results!B:B, 1) + COUNTIFS(Results!$I:$I, $A29, Results!$G:$G, $N$21, Results!B:B, 0) -> 0 | P29: =COUNTIFS(Results!$I:$I, $A29, Results!$G:$G, $N$21, Results!B:B, 1) -> 0 | Q29: =IFERROR(P29/O29, 0) -> 0 | R29: =G9 -> 1
A30: casEN_opti | B30: =COUNTIFS(Results!$I:$I, A30, Results!$G:$G, $B$21) -> 152 | C30: =COUNTIFS(Results!$I:$I, A30, Results!$G:$G, $B$21, Results!B:B, 1) + COUNTIFS(Results!$I:$I, A30, Results!$G:$G, $B$21, Results!B:B, 0) -> 61 | D30: =COUNTIFS(Results!$I:$I, A30, Results!$G:$G, $B$21, Results!B:B, 1) -> 48 | E30: =IFERROR(D30/C30, 0) -> 0.78688525 | F30: =COUNTIFS(Results!$I:$I, $A30, Results!$G:$G, $F$21) -> 268 | G30: =COUNTIFS(Results!$I:$I, $A30, Results!$G:$G, $F$21, Results!B:B, 1) + COUNTIFS(Results!$I:$I, $A30, Results!$G:$G, $F$21, Results!B:B, 0) -> 246 | H30: =COUNTIFS(Results!$I:$I, $A30, Results!$G:$G, $F$21, Results!B:B, 1) -> 228 | I30: =IFERROR(H30/G30, 0) -> 0.92682927 | J30: =COUNTIFS(Results!$I:$I, $A30,Results!$G:$G, $J$21) -> 85 | K30: =COUNTIFS(Results!$I:$I, $A30,Results!$G:$G, $J$21, Results!B:B, 1) + COUNTIFS(Results!$I:$I, $A30,Results!$G:$G, $J$21, Results!B:B, 0) -> 71 | L30: =COUNTIFS(Results!$I:$I, $A30,Results!$G:$G, $J$21, Results!B:B, 1) -> 64 | M30: =IFERROR(L30/K30, 0) -> 0.90140845 | N30: =COUNTIFS(Results!$I:$I, $A30, Results!$G:$G, $N$21) -> 0 | O30: =COUNTIFS(Results!$I:$I, $A30, Results!$G:$G, $N$21, Results!B:B, 1) + COUNTIFS(Results!$I:$I, $A30, Results!$G:$G, $N$21, Results!B:B, 0) -> 0 | P30: =COUNTIFS(Results!$I:$I, $A30, Results!$G:$G, $N$21, Results!B:B, 1) -> 0 | Q30: =IFERROR(P30/O30, 0) -> 0 | R30: =G10 -> 1
A31: casEN_spaCy | B31: =COUNTIFS(Results!$I:$I, A31, Results!$G:$G, $B$21) -> 135 | C31: =COUNTIFS(Results!$I:$I, A31, Results!$G:$G, $B$21, Results!B:B, 1) + COUNTIFS(Results!$I:$I, A31, Results!$G:$G, $B$21, Results!B:B, 0) -> 127 | D31: =COUNTIFS(Results!$I:$I, A31, Results!$G:$G, $B$21, Results!B:B, 1) -> 116 | E31: =IFERROR(D31/C31, 0) -> 0.91338583 | F31: =COUNTIFS(Results!$I:$I, $A31, Results!$G:$G, $F$21) -> 68 | G31: =COUNTIFS(Results!$I:$I, $A31, Results!$G:$G, $F$21, Results!B:B, 1) + COUNTIFS(Results!$I:$I, $A31, Results!$G:$G, $F$21, Results!B:B, 0) -> 60 | H31: =COUNTIFS(Results!$I:$I, $A31, Results!$G:$G, $F$21, Results!B:B, 1) -> 53 | I31: =IFERROR(H31/G31, 0) -> 0.88333333 | J31: =COUNTIFS(Results!$I:$I, $A31,Results!$G:$G, $J$21) -> 57 | K31: =COUNTIFS(Results!$I:$I, $A31,Results!$G:$G, $J$21, Results!B:B, 1) + COUNTIFS(Results!$I:$I, $A31,Results!$G:$G, $J$21, Results!B:B, 0) -> 49 | L31: =COUNTIFS(Results!$I:$I, $A31,Results!$G:$G, $J$21, Results!B:B, 1) -> 10 | M31: =IFERROR(L31/K31, 0) -> 0.20408163 | N31: =COUNTIFS(Results!$I:$I, $A31, Results!$G:$G, $N$21) -> 0 | O31: =COUNTIFS(Results!$I:$I, $A31, Results!$G:$G, $N$21, Results!B:B, 1) + COUNTIFS(Results!$I:$I, $A31, Results!$G:$G, $N$21, Results!B:B, 0) -> 0 | P31: =COUNTIFS(Results!$I:$I, $A31, Results!$G:$G, $N$21, Results!B:B, 1) -> 0 | Q31: =IFERROR(P31/O31, 0) -> 0 | R31: =G11 -> 0
A32: casEN_spaCy_priority | B32: =COUNTIFS(Results!$I:$I, A32, Results!$G:$G, $B$21) -> 110 | C32: =COUNTIFS(Results!$I:$I, A32, Results!$G:$G, $B$21, Results!B:B, 1) + COUNTIFS(Results!$I:$I, A32, Results!$G:$G, $B$21, Results!B:B, 0) -> 102 | D32: =COUNTIFS(Results!$I:$I, A32, Results!$G:$G, $B$21, Results!B:B, 1) -> 76 | E32: =IFERROR(D32/C32, 0) -> 0.74509804 | F32: =COUNTIFS(Results!$I:$I, $A32, Results!$G:$G, $F$21) -> 0 | G32: =COUNTIFS(Results!$I:$I, $A32, Results!$G:$G, $F$21, Results!B:B, 1) + COUNTIFS(Results!$I:$I, $A32, Results!$G:$G, $F$21, Results!B:B, 0) -> 0 | H32: =COUNTIFS(Results!$I:$I, $A32, Results!$G:$G, $F$21, Results!B:B, 1) -> 0 | I32: =IFERROR(H32/G32, 0) -> 0 | J32: =COUNTIFS(Results!$I:$I, $A32,Results!$G:$G, $J$21) -> 0 | K32: =COUNTIFS(Results!$I:$I, $A32,Results!$G:$G, $J$21, Results!B:B, 1) + COUNTIFS(Results!$I:$I, $A32,Results!$G:$G, $J$21, Results!B:B, 0) -> 0 | L32: =COUNTIFS(Results!$I:$I, $A32,Results!$G:$G, $J$21, Results!B:B, 1) -> 0 | M32: =IFERROR(L32/K32, 0) -> 0 | N32: =COUNTIFS(Results!$I:$I, $A32, Results!$G:$G, $N$21) -> 0 | O32: =COUNTIFS(Results!$I:$I, $A32, Results!$G:$G, $N$21, Results!B:B, 1) + COUNTIFS(Results!$I:$I, $A32, Results!$G:$G, $N$21, Results!B:B, 0) -> 0 | P32: =COUNTIFS(Results!$I:$I, $A32, Results!$G:$G, $N$21, Results!B:B, 1) -> 0 | Q32: =IFERROR(P32/O32, 0) -> 0 | R32: =G12 -> 0
A35: Total | B35: =SUM(B22:B33) -> 15723 | F35: =SUM(F22:F33) -> 8645 | J35: =SUM(J22:J33) -> 4317 | N35: =SUM(N22:N33) -> 6958
A36: pourcentage | B36: =B35/(B35+F35+J35+N35) -> 0.44112448 | F36: =F35/(F35+B35+J35+N35) -> 0.24254412 | J36: =J35/(B35+F35+J35+N35) -> 0.12111775 | N36: =N35/(N35+J35+F35+B35) -> 0.19521365
A40: Corrected | B40: =C2+C3+C4+C5+C6+C7+C8+C9+C10+C11+C12+C13 -> 19341
A41: Missing correction | B41: =COUNTA(Results!M:M) - B40 -> 16303

Sheet graphs_analyses
A1: {=_xlfn.UNIQUE(_xlfn._xlws.FILTER(Results!J:J, Results!J:J<>""))} -> main_graph | B1: Total Founds | C1: Corrected | D1: Correct | E1: Total Accuracy | F1: casEN_spaCy_stanza | G1: Corrected | H1: Correct | I1: Accuracy | J1: Only CasEN | K1: Corrected | L1: Correct | M1: Accuracy | N1: Global Accuray Loss | R1: main_graph | S1: second_graph | T1: Total Founds | U1: Corrected | V1: Correct | W1: Total Accuracy | X1: casEN_spaCy_stanza | Y1: Corrected | Z1: Correct | AA1: Accuracy | AB1: Only CasEN | AC1: Corrected | AD1: Correct | AE1: Accuracy | AF1: Global Accuray Loss | AJ1: main_graph | AK1: second_graph | AL1: third_graph | AM1: Total Founds | AN1: Corrected | AO1: Correct | AP1: Total Accuracy | AQ1: casEN_spaCy_stanza | AR1: Corrected | AS1: Correct | AT1: Accuracy | AU1: Only CasEN | AV1: Corrected | AW1: Correct | AX1: Accuracy | AY1: Global Accuray Loss
A2: grfpersGenerique | B2: =COUNTIF(Results!J:J, A2) -> 5005 | C2: =COUNTIFS(Results!J:J, A2, Results!B:B, 1) + COUNTIFS(Results!J:J, A2, Results!B:B, 0) -> 2941 | D2: =COUNTIFS(Results!J:J, A2, Results!B:B, 1) -> 2796 | E2: =IF(C2=0, 0, D2/C2) -> 0.95069704 | F2: =COUNTIFS(Results!J:J, A2, Results!I:I, $F$1) -> 2181 | G2: =COUNTIFS(Results!J:J, A2, Results!B:B, 1, Results!I:I, $F$1) + COUNTIFS(Results!J:J, A2, Results!B:B, 0, Results!I:I, $F$1) -> 2023 | H2: =COUNTIFS(Results!I:I, $F$1,Results!J:J, A2, Results!B:B, 1) -> 2001 | I2: =IFERROR(H2/G2, 0) -> 0.98912506 | J2: =COUNTIFS(Results!J:J, A2, Results!I:I, "casEN") + COUNTIFS(Results!J:J, A2, Results!I:I, "casEN_opti") -> 1445 | K2: =COUNTIFS(Results!J:J, A2, Results!B:B, 1, Results!I:I, "casEN") + COUNTIFS(Results!J:J, A2, Results!B:B, 0, Results!I:I, "casEN") + COUNTIFS(Results!J:J, A2, Results!B:B, 1, Results!I:I, "casEN_opti") + COUNTIFS(Results!J:J, A2, Results!B:B, 0, Results!I:I, "casEN_opti") -> 197 | L2: =COUNTIFS(Results!I:I, "casEN",Results!J:J, A2, Results!B:B, 1) + COUNTIFS(Results!I:I, "casEN_opti",Results!J:J, A2, Results!B:B, 1) -> 139 | M2: =IFERROR(L2/K2, 0) -> 0.70558376 | N2: =(NER!$L$11+graphs_analyses!L2)/(graphs_analyses!K2 +NER!$K$11) - NER!$M$11 -> -0.0073608231 | R2: {=_xlfn._xlws.SORT( _xlfn.UNIQUE(_xlfn._xlws.FILTER(Results!J:K, (Results!J:J<>"")*(Results!K:K<>""))), 1, TRUE )} -> grfadress | S2: grftagAdresseRue | T2: =COUNTIFS(Results!J:J, R2, Results!K:K, S2) -> 75 | U2: =COUNTIFS(Results!J:J, R2,Results!K:K, S2, Results!B:B, 1) + COUNTIFS(Results!J:J, R2,Results!K:K, S2, Results!B:B, 0) -> 9 | V2: =COUNTIFS(Results!J:J, R2, Results!K:K, S2, Results!B:B, 1) -> 4 | W2: =IFERROR(V2/U2, 0) -> 0.44444444 | X2: =COUNTIFS(Results!J:J, R2, Results!K:K, S2, Results!I:I, $X$1) -> 6 | Y2: =COUNTIFS(Results!J:J, R2,Results!K:K, S2, Results!I:I, $X$1, Results!B:B, 1) + COUNTIFS(Results!J:J, R2,Results!K:K, S2,Results!I:I, $X$1, Results!B:B, 0) -> 6 | Z2: =COUNTIFS(Results!J:J, R2, Results!K:K, S2, Results!I:I, $X$1, Results!B:B, 1) -> 4 | AA2: =IFERROR(Z2/Y2, 0) -> 0.66666667 | AB2: =COUNTIFS(Results!J:J, R2,Results!K:K, S2, Results!I:I, "casEN") + COUNTIFS(Results!J:J, R2,Results!K:K, S2, Results!I:I, "casEN_opti") -> 60 | AC2: =COUNTIFS(Results!J:J, R2,Results!K:K, S2, Results!B:B, 1, Results!I:I, "casEN") + COUNTIFS(Results!J:J, R2,Results!K:K, S2, Results!B:B, 0, Results!I:I, "casEN") + COUNTIFS(Results!J:J, R2,Results!K:K, S2, Results!B:B, 1, Results!I:I, "casEN_opti") + COUNTIFS(Results!J:J, R2,Results!K:K, S2, Results!B:B, 0, Results!I:I, "casEN_opti") -> 3 | AD2: =COUNTIFS(Results!J:J, R2,Results!K:K, S2, Results!B:B, 1, Results!I:I, "casEN") + COUNTIFS(Results!J:J, R2,Results!K:K, S2, Results!B:B, 1, Results!I:I, "casEN_opti") -> 0 | AE2: =IFERROR(AD2/AC2, 0) -> 0 | AF2: =(NER!$L$11+graphs_analyses!AD2)/(graphs_analyses!AC2 +NER!$K$11) - NER!$M$11 -> -0.00041961424 | AJ2: {=_xlfn._xlws.SORT( _xlfn.UNIQUE(_xlfn._xlws.FILTER(Results!J:L, (Results!J:J<>"")*(Results!K:K<>"")*(Results!L:L<>""))), 1, TRUE )} -> grfadress | AK2: grftagZoneIndustrielle | AL2: grftagZoneIndustrielle | AM2: =COUNTIFS(Results!J:J, AJ2, Results!K:K, AK2, Results!L:L, AL2) -> 1 | AN2: =COUNTIFS(Results!J:J, AJ2, Results!K:K, AK2, Results!L:L, AL2, Results!B:B, 1) + COUNTIFS(Results!J:J, AJ2, Results!K:K, AK2, Results!L:L, AL2, Results!B:B, 0) -> 0 | AO2: =COUNTIFS(Results!J:J, AJ2, Results!K:K, AK2, Results!L:L, AL2, Results!B:B, 1) -> 0 | AP2: =IFERROR(AO2/AN2, 0) -> 0 | AQ2: =COUNTIFS(Results!J:J, AJ2, Results!K:K, AK2, Results!L:L, AL2, Results!I:I, $AQ$1) -> 0 | AR2: =COUNTIFS(Results!J:J, AJ2, Results!K:K, AK2, Results!L:L, AL2, Results!I:I, $AQ$1, Results!B:B, 1) + COUNTIFS(Results!J:J, AJ2, Results!K:K, AK2, Results!L:L, AL2, Results!I:I, $AQ$1, Results!B:B, 0) -> 0 | AS2: =COUNTIFS(Results!J:J, AJ2, Results!K:K, AK2, Results!L:L, AL2, Results!I:I, $AQ$1, Results!B:B, 1) -> 0 | AT2: =IFERROR(AS2/AR2, 0) -> 0 | AU2: =COUNTIFS(Results!J:J, AJ2,Results!K:K, AK2, Results!L:L, AL2,Results!I:I, "casEN") + COUNTIFS(Results!J:J, AJ2,Results!K:K, AK2, Results!L:L, AL2,Results!I:I, "casEN_opti") -> 1 | AV2: =COUNTIFS(Results!J:J, AJ2,Results!K:K, AK2, Results!L:L, AL2,Results!I:I, "casEN", Results!B:B, 1) + COUNTIFS(Results!J:J, AJ2,Results!K:K, AK2, Results!L:L, AL2,Results!I:I, "casEN", Results!B:B, 0) + COUNTIFS(Results!J:J, AJ2,Results!K:K, AK2, Results!L:L, AL2,Results!I:I, "casEN_opti", Results!B:B, 1) + COUNTIFS(Results!J:J, AJ2,Results!K:K, AK2, Results!L:L, AL2,Results!I:I, "casEN_opti", Results!B:B, 0) -> 0 | AW2: =COUNTIFS(Results!J:J, AJ2,Results!K:K, AK2, Results!L:L, AL2,Results!I:I, "casEN", Results!B:B, 1) + COUNTIFS(Results!J:J, AJ2,Results!K:K, AK2, Results!L:L, AL2,Results!I:I, "casEN_opti", Results!B:B, 1) -> 0 | AX2: =IFERROR(AW2/AV2, 0) -> 0 | AY2: =(NER!$L$11+graphs_analyses!AW2)/(graphs_analyses!AV2 +NER!$K$11) - NER!$M$11 -> 0
A3: grfpersPrenomNom | B3: =COUNTIF(Results!J:J, A3) -> 2359 | C3: =COUNTIFS(Results!J:J, A3, Results!B:B, 1) + COUNTIFS(Results!J:J, A3, Results!B:B, 0) -> 2354 | D3: =COUNTIFS(Results!J:J, A3, Results!B:B, 1) -> 2147 | E3: =IF(C3=0, 0, D3/C3) -> 0.91206457 | F3: =COUNTIFS(Results!J:J, A3, Results!I:I, $F$1) -> 1845 | G3: =COUNTIFS(Results!J:J, A3, Results!B:B, 1, Results!I:I, $F$1) + COUNTIFS(Results!J:J, A3, Results!B:B, 0, Results!I:I, $F$1) -> 1845 | H3: =COUNTIFS(Results!I:I, $F$1,Results!J:J, A3, Results!B:B, 1) -> 1834 | I3: =IFERROR(H3/G3, 0) -> 0.99403794 | J3: =COUNTIFS(Results!J:J, A3, Results!I:I, "casEN") + COUNTIFS(Results!J:J, A3, Results!I:I, "casEN_opti") -> 227 | K3: =COUNTIFS(Results!J:J, A3, Results!B:B, 1, Results!I:I, "casEN") + COUNTIFS(Results!J:J, A3, Results!B:B, 0, Results!I:I, "casEN") + COUNTIFS(Results!J:J, A3, Results!B:B, 1, Results!I:I, "casEN_opti") + COUNTIFS(Results!J:J, A3, Results!B:B, 0, Results!I:I, "casEN_opti") -> 222 | L3: =COUNTIFS(Results!I:I, "casEN",Results!J:J, A3, Results!B:B, 1) + COUNTIFS(Results!I:I, "casEN_opti",Results!J:J, A3, Results!B:B, 1) -> 57 | M3: =IFERROR(L3/K3, 0) -> 0.25675676 | N3: =(NER!$L$11+graphs_analyses!L3)/(graphs_analyses!K3 +NER!$K$11) - NER!$M$11 -> -0.022156951 | R3: grfadress | S3: grftagZoneIndustrielle | T3: =COUNTIFS(Results!J:J, R3, Results!K:K, S3) -> 18 | U3: =COUNTIFS(Results!J:J, R3,Results!K:K, S3, Results!B:B, 1) + COUNTIFS(Results!J:J, R3,Results!K:K, S3, Results!B:B, 0) -> 0 | V3: =COUNTIFS(Results!J:J, R3, Results!K:K, S3, Results!B:B, 1) -> 0 | W3: =IFERROR(V3/U3, 0) -> 0 | X3: =COUNTIFS(Results!J:J, R3, Results!K:K, S3, Results!I:I, $X$1) -> 0 | Y3: =COUNTIFS(Results!J:J, R3,Results!K:K, S3, Results!I:I, $X$1, Results!B:B, 1) + COUNTIFS(Results!J:J, R3,Results!K:K, S3,Results!I:I, $X$1, Results!B:B, 0) -> 0 | Z3: =COUNTIFS(Results!J:J, R3, Results!K:K, S3, Results!I:I, $X$1, Results!B:B, 1) -> 0 | AA3: =IFERROR(Z3/Y3, 0) -> 0 | AB3: =COUNTIFS(Results!J:J, R3,Results!K:K, S3, Results!I:I, "casEN") + COUNTIFS(Results!J:J, R3,Results!K:K, S3, Results!I:I, "casEN_opti") -> 18 | AC3: =COUNTIFS(Results!J:J, R3,Results!K:K, S3, Results!B:B, 1, Results!I:I, "casEN") + COUNTIFS(Results!J:J, R3,Results!K:K, S3, Results!B:B, 0, Results!I:I, "casEN") + COUNTIFS(Results!J:J, R3,Results!K:K, S3, Results!B:B, 1, Results!I:I, "casEN_opti") + COUNTIFS(Results!J:J, R3,Results!K:K, S3, Results!B:B, 0, Results!I:I, "casEN_opti") -> 0 | AD3: =COUNTIFS(Results!J:J, R3,Results!K:K, S3, Results!B:B, 1, Results!I:I, "casEN") + COUNTIFS(Results!J:J, R3,Results!K:K, S3, Results!B:B, 1, Results!I:I, "casEN_opti") -> 0 | AE3: =IFERROR(AD3/AC3, 0) -> 0 | AF3: =(NER!$L$11+graphs_analyses!AD3)/(graphs_analyses!AC3 +NER!$K$11) - NER!$M$11 -> 0 | AJ3: grforgSeule | AK3: grforgProximite | AL3: grfpersGenerique | AM3: =COUNTIFS(Results!J:J, AJ3, Results!K:K, AK3, Results!L:L, AL3) -> 7 | AN3: =COUNTIFS(Results!J:J, AJ3, Results!K:K, AK3, Results!L:L, AL3, Results!B:B, 1) + COUNTIFS(Results!J:J, AJ3, Results!K:K, AK3, Results!L:L, AL3, Results!B:B, 0) -> 5 | AO3: =COUNTIFS(Results!J:J, AJ3, Results!K:K, AK3, Results!L:L, AL3, Results!B:B, 1) -> 1 | AP3: =IFERROR(AO3/AN3, 0) -> 0.2 | AQ3: =COUNTIFS(Results!J:J, AJ3, Results!K:K, AK3, Results!L:L, AL3, Results!I:I, $AQ$1) -> 0 | AR3: =COUNTIFS(Results!J:J, AJ3, Results!K:K, AK3, Results!L:L, AL3, Results!I:I, $AQ$1, Results!B:B, 1) + COUNTIFS(Results!J:J, AJ3, Results!K:K, AK3, Results!L:L, AL3, Results!I:I, $AQ$1, Results!B:B, 0) -> 0 | AS3: =COUNTIFS(Results!J:J, AJ3, Results!K:K, AK3, Results!L:L, AL3, Results!I:I, $AQ$1, Results!B:B, 1) -> 0 | AT3: =IFERROR(AS3/AR3, 0) -> 0 | AU3: =COUNTIFS(Results!J:J, AJ3,Results!K:K, AK3, Results!L:L, AL3,Results!I:I, "casEN") + COUNTIFS(Results!J:J, AJ3,Results!K:K, AK3, Results!L:L, AL3,Results!I:I, "casEN_opti") -> 6 | AV3: =COUNTIFS(Results!J:J, AJ3,Results!K:K, AK3, Results!L:L, AL3,Results!I:I, "casEN", Results!B:B, 1) + COUNTIFS(Results!J:J, AJ3,Results!K:K, AK3, Results!L:L, AL3,Results!I:I, "casEN", Results!B:B, 0) + COUNTIFS(Results!J:J, AJ3,Results!K:K, AK3, Results!L:L, AL3,Results!I:I, "casEN_opti", Results!B:B, 1) + COUNTIFS(Results!J:J, AJ3,Results!K:K, AK3, Results!L:L, AL3,Results!I:I, "casEN_opti", Results!B:B, 0) -> 5 | AW3: =COUNTIFS(Results!J:J, AJ3,Results!K:K, AK3, Results!L:L, AL3,Results!I:I, "casEN", Results!B:B, 1) + COUNTIFS(Results!J:J, AJ3,Results!K:K, AK3, Results!L:L, AL3,Results!I:I, "casEN_opti", Results!B:B, 1) -> 1 | AX3: =IFERROR(AW3/AV3, 0) -> 0.2 | AY3: =(NER!$L$11+graphs_analyses!AW3)/(graphs_analyses!AV3 +NER!$K$11) - NER!$M$11 -> -0.0005553952
A4: grforgProximite | B4: =COUNTIF(Results!J:J, A4) -> 962 | C4: =COUNTIFS(Results!J:J, A4, Results!B:B, 1) + COUNTIFS(Results!J:J, A4, Results!B:B, 0) -> 30 | D4: =COUNTIFS(Results!J:J, A4, Results!B:B, 1) -> 8 | E4: =IF(C4=0, 0, D4/C4) -> 0.26666667 | F4: =COUNTIFS(Results!J:J, A4, Results!I:I, $F$1) -> 1 | G4: =COUNTIFS(Results!J:J, A4, Results!B:B, 1, Results!I:I, $F$1) + COUNTIFS(Results!J:J, A4, Results!B:B, 0, Results!I:I, $F$1) -> 1 | H4: =COUNTIFS(Results!I:I, $F$1,Results!J:J, A4, Results!B:B, 1) -> 0 | I4: =IFERROR(H4/G4, 0) -> 0 | J4: =COUNTIFS(Results!J:J, A4, Results!I:I, "casEN") + COUNTIFS(Results!J:J, A4, Results!I:I, "casEN_opti") -> 953 | K4: =COUNTIFS(Results!J:J, A4, Results!B:B, 1, Results!I:I, "casEN") + COUNTIFS(Results!J:J, A4, Results!B:B, 0, Results!I:I, "casEN") + COUNTIFS(Results!J:J, A4, Results!B:B, 1, Results!I:I, "casEN_opti") + COUNTIFS(Results!J:J, A4, Results!B:B, 0, Results!I:I, "casEN_opti") -> 22 | L4: =COUNTIFS(Results!I:I, "casEN",Results!J:J, A4, Results!B:B, 1) + COUNTIFS(Results!I:I, "casEN_opti",Results!J:J, A4, Results!B:B, 1) -> 5 | M4: =IFERROR(L4/K4, 0) -> 0.22727273 | N4: =(NER!$L$11+graphs_analyses!L4)/(graphs_analyses!K4 +NER!$K$11) - NER!$M$11 -> -0.0023517349 | R4: grfgeog | S4: grftoolPolylexicalOrgPlace | T4: =COUNTIFS(Results!J:J, R4, Results!K:K, S4) -> 40 | U4: =COUNTIFS(Results!J:J, R4,Results!K:K, S4, Results!B:B, 1) + COUNTIFS(Results!J:J, R4,Results!K:K, S4, Results!B:B, 0) -> 40 | V4: =COUNTIFS(Results!J:J, R4, Results!K:K, S4, Results!B:B, 1) -> 40 | W4: =IFERROR(V4/U4, 0) -> 1 | X4: =COUNTIFS(Results!J:J, R4, Results!K:K, S4, Results!I:I, $X$1) -> 35 | Y4: =COUNTIFS(Results!J:J, R4,Results!K:K, S4, Results!I:I, $X$1, Results!B:B, 1) + COUNTIFS(Results!J:J, R4,Results!K:K, S4,Results!I:I, $X$1, Results!B:B, 0) -> 35 | Z4: =COUNTIFS(Results!J:J, R4, Results!K:K, S4, Results!I:I, $X$1, Results!B:B, 1) -> 35 | AA4: =IFERROR(Z4/Y4, 0) -> 1 | AB4: =COUNTIFS(Results!J:J, R4,Results!K:K, S4, Results!I:I, "casEN") + COUNTIFS(Results!J:J, R4,Results!K:K, S4, Results!I:I, "casEN_opti") -> 3 | AC4: =COUNTIFS(Results!J:J, R4,Results!K:K, S4, Results!B:B, 1, Results!I:I, "casEN") + COUNTIFS(Results!J:J, R4,Results!K:K, S4, Results!B:B, 0, Results!I:I, "casEN") + COUNTIFS(Results!J:J, R4,Results!K:K, S4, Results!B:B, 1, Results!I:I, "casEN_opti") + COUNTIFS(Results!J:J, R4,Results!K:K, S4, Results!B:B, 0, Results!I:I, "casEN_opti") -> 3 | AD4: =COUNTIFS(Results!J:J, R4,Results!K:K, S4, Results!B:B, 1, Results!I:I, "casEN") + COUNTIFS(Results!J:J, R4,Results!K:K, S4, Results!B:B, 1, Results!I:I, "casEN_opti") -> 3 | AE4: =IFERROR(AD4/AC4, 0) -> 1 | AF4: =(NER!$L$11+graphs_analyses!AD4)/(graphs_analyses!AC4 +NER!$K$11) - NER!$M$11 -> 1.1792147e-05 | AJ4: grforgSeule | AK4: grforgArmee | AL4: grfpersPrenomNom | AM4: =COUNTIFS(Results!J:J, AJ4, Results!K:K, AK4, Results!L:L, AL4) -> 1 | AN4: =COUNTIFS(Results!J:J, AJ4, Results!K:K, AK4, Results!L:L, AL4, Results!B:B, 1) + COUNTIFS(Results!J:J, AJ4, Results!K:K, AK4, Results!L:L, AL4, Results!B:B, 0) -> 1 | AO4: =COUNTIFS(Results!J:J, AJ4, Results!K:K, AK4, Results!L:L, AL4, Results!B:B, 1) -> 1 | AP4: =IFERROR(AO4/AN4, 0) -> 1 | AQ4: =COUNTIFS(Results!J:J, AJ4, Results!K:K, AK4, Results!L:L, AL4, Results!I:I, $AQ$1) -> 0 | AR4: =COUNTIFS(Results!J:J, AJ4, Results!K:K, AK4, Results!L:L, AL4, Results!I:I, $AQ$1, Results!B:B, 1) + COUNTIFS(Results!J:J, AJ4, Results!K:K, AK4, Results!L:L, AL4, Results!I:I, $AQ$1, Results!B:B, 0) -> 0 | AS4: =COUNTIFS(Results!J:J, AJ4, Results!K:K, AK4, Results!L:L, AL4, Results!I:I, $AQ$1, Results!B:B, 1) -> 0 | AT4: =IFERROR(AS4/AR4, 0) -> 0 | AU4: =COUNTIFS(Results!J:J, AJ4,Results!K:K, AK4, Results!L:L, AL4,Results!I:I, "casEN") + COUNTIFS(Results!J:J, AJ4,Results!K:K, AK4, Results!L:L, AL4,Results!I:I, "casEN_opti") -> 1 | AV4: =COUNTIFS(Results!J:J, AJ4,Results!K:K, AK4, Results!L:L, AL4,Results!I:I, "casEN", Results!B:B, 1) + COUNTIFS(Results!J:J, AJ4,Results!K:K, AK4, Results!L:L, AL4,Results!I:I, "casEN", Results!B:B, 0) + COUNTIFS(Results!J:J, AJ4,Results!K:K, AK4, Results!L:L, AL4,Results!I:I, "casEN_opti", Results!B:B, 1) + COUNTIFS(Results!J:J, AJ4,Results!K:K, AK4, Results!L:L, AL4,Results!I:I, "casEN_opti", Results!B:B, 0) -> 1 | AW4: =COUNTIFS(Results!J:J, AJ4,Results!K:K, AK4, Results!L:L, AL4,Results!I:I, "casEN", Results!B:B, 1) + COUNTIFS(Results!J:J, AJ4,Results!K:K, AK4, Results!L:L, AL4,Results!I:I, "casEN_opti", Results!B:B, 1) -> 1 | AX4: =IFERROR(AW4/AV4, 0) -> 1 | AY4: =(NER!$L$11+graphs_analyses!AW4)/(graphs_analyses!AV4 +NER!$K$11) - NER!$M$11 -> 3.9318464e-06
A5: grforgSeule | B5: =COUNTIF(Results!J:J, A5) -> 240 | C5: =COUNTIFS(Results!J:J, A5, Results!B:B, 1) + COUNTIFS(Results!J:J, A5, Results!B:B, 0) -> 196 | D5: =COUNTIFS(Results!J:J, A5, Results!B:B, 1) -> 116 | E5: =IF(C5=0, 0, D5/C5) -> 0.59183673 | F5: =COUNTIFS(Results!J:J, A5, Results!I:I, $F$1) -> 12 | G5: =COUNTIFS(Results!J:J, A5, Results!B:B, 1, Results!I:I, $F$1) + COUNTIFS(Results!J:J, A5, Results!B:B, 0, Results!I:I, $F$1) -> 12 | H5: =COUNTIFS(Results!I:I, $F$1,Results!J:J, A5, Results!B:B, 1) -> 12 | I5: =IFERROR(H5/G5, 0) -> 1 | J5: =COUNTIFS(Results!J:J, A5, Results!I:I, "casEN") + COUNTIFS(Results!J:J, A5, Results!I:I, "casEN_opti") -> 218 | K5: =COUNTIFS(Results!J:J, A5, Results!B:B, 1, Results!I:I, "casEN") + COUNTIFS(Results!J:J, A5, Results!B:B, 0, Results!I:I, "casEN") + COUNTIFS(Results!J:J, A5, Results!B:B, 1, Results!I:I, "casEN_opti") + COUNTIFS(Results!J:J, A5, Results!B:B, 0, Results!I:I, "casEN_opti") -> 177 | L5: =COUNTIFS(Results!I:I, "casEN",Results!J:J, A5, Results!B:B, 1) + COUNTIFS(Results!I:I, "casEN_opti",Results!J:J, A5, Results!B:B, 1) -> 99 | M5: =IFERROR(L5/K5, 0) -> 0.55932203 | N5: =(NER!$L$11+graphs_analyses!L5)/(graphs_analyses!K5 +NER!$K$11) - NER!$M$11 -> -0.010264008 | R5: grfgeog | S5: grforgPlaceGeoPolitique | T5: =COUNTIFS(Results!J:J, R5, Results!K:K, S5) -> 32 | U5: =COUNTIFS(Results!J:J, R5,Results!K:K, S5, Results!B:B, 1) + COUNTIFS(Results!J:J, R5,Results!K:K, S5, Results!B:B, 0) -> 23 | V5: =COUNTIFS(Results!J:J, R5, Results!K:K, S5, Results!B:B, 1) -> 23 | W5: =IFERROR(V5/U5, 0) -> 1 | X5: =COUNTIFS(Results!J:J, R5, Results!K:K, S5, Results!I:I, $X$1) -> 0 | Y5: =COUNTIFS(Results!J:J, R5,Results!K:K, S5, Results!I:I, $X$1, Results!B:B, 1) + COUNTIFS(Results!J:J, R5,Results!K:K, S5,Results!I:I, $X$1, Results!B:B, 0) -> 0 | Z5: =COUNTIFS(Results!J:J, R5, Results!K:K, S5, Results!I:I, $X$1, Results!B:B, 1) -> 0 | AA5: =IFERROR(Z5/Y5, 0) -> 0 | AB5: =COUNTIFS(Results!J:J, R5,Results!K:K, S5, Results!I:I, "casEN") + COUNTIFS(Results!J:J, R5,Results!K:K, S5, Results!I:I, "casEN_opti") -> 30 | AC5: =COUNTIFS(Results!J:J, R5,Results!K:K, S5, Results!B:B, 1, Results!I:I, "casEN") + COUNTIFS(Results!J:J, R5,Results!K:K, S5, Results!B:B, 0, Results!I:I, "casEN") + COUNTIFS(Results!J:J, R5,Results!K:K, S5, Results!B:B, 1, Results!I:I, "casEN_opti") + COUNTIFS(Results!J:J, R5,Results!K:K, S5, Results!B:B, 0, Results!I:I, "casEN_opti") -> 21 | AD5: =COUNTIFS(Results!J:J, R5,Results!K:K, S5, Results!B:B, 1, Results!I:I, "casEN") + COUNTIFS(Results!J:J, R5,Results!K:K, S5, Results!B:B, 1, Results!I:I, "casEN_opti") -> 21 | AE5: =IFERROR(AD5/AC5, 0) -> 1 | AF5: =(NER!$L$11+graphs_analyses!AD5)/(graphs_analyses!AC5 +NER!$K$11) - NER!$M$11 -> 8.2331917e-05 | AJ5: grforgSeule | AK5: grforgFinance | AL5: grfpersPrenomNom | AM5: =COUNTIFS(Results!J:J, AJ5, Results!K:K, AK5, Results!L:L, AL5) -> 1 | AN5: =COUNTIFS(Results!J:J, AJ5, Results!K:K, AK5, Results!L:L, AL5, Results!B:B, 1) + COUNTIFS(Results!J:J, AJ5, Results!K:K, AK5, Results!L:L, AL5, Results!B:B, 0) -> 1 | AO5: =COUNTIFS(Results!J:J, AJ5, Results!K:K, AK5, Results!L:L, AL5, Results!B:B, 1) -> 0 | AP5: =IFERROR(AO5/AN5, 0) -> 0 | AQ5: =COUNTIFS(Results!J:J, AJ5, Results!K:K, AK5, Results!L:L, AL5, Results!I:I, $AQ$1) -> 0 | AR5: =COUNTIFS(Results!J:J, AJ5, Results!K:K, AK5, Results!L:L, AL5, Results!I:I, $AQ$1, Results!B:B, 1) + COUNTIFS(Results!J:J, AJ5, Results!K:K, AK5, Results!L:L, AL5, Results!I:I, $AQ$1, Results!B:B, 0) -> 0 | AS5: =COUNTIFS(Results!J:J, AJ5, Results!K:K, AK5, Results!L:L, AL5, Results!I:I, $AQ$1, Results!B:B, 1) -> 0 | AT5: =IFERROR(AS5/AR5, 0) -> 0 | AU5: =COUNTIFS(Results!J:J, AJ5,Results!K:K, AK5, Results!L:L, AL5,Results!I:I, "casEN") + COUNTIFS(Results!J:J, AJ5,Results!K:K, AK5, Results!L:L, AL5,Results!I:I, "casEN_opti") -> 1 | AV5: =COUNTIFS(Results!J:J, AJ5,Results!K:K, AK5, Results!L:L, AL5,Results!I:I, "casEN", Results!B:B, 1) + COUNTIFS(Results!J:J, AJ5,Results!K:K, AK5, Results!L:L, AL5,Results!I:I, "casEN", Results!B:B, 0) + COUNTIFS(Results!J:J, AJ5,Results!K:K, AK5, Results!L:L, AL5,Results!I:I, "casEN_opti", Results!B:B, 1) + COUNTIFS(Results!J:J, AJ5,Results!K:K, AK5, Results!L:L, AL5,Results!I:I, "casEN_opti", Results!B:B, 0) -> 1 | AW5: =COUNTIFS(Results!J:J, AJ5,Results!K:K, AK5, Results!L:L, AL5,Results!I:I, "casEN", Results!B:B, 1) + COUNTIFS(Results!J:J, AJ5,Results!K:K, AK5, Results!L:L, AL5,Results!I:I, "casEN_opti", Results!B:B, 1) -> 0 | AX5: =IFERROR(AW5/AV5, 0) -> 0 | AY5: =(NER!$L$11+graphs_analyses!AW5)/(graphs_analyses!AV5 +NER!$K$11) - NER!$M$11 -> -0.00013991165
A6: grfpersContextePersonne | B6: =COUNTIF(Results!J:J, A6) -> 324 | C6: =COUNTIFS(Results!J:J, A6, Results!B:B, 1) + COUNTIFS(Results!J:J, A6, Results!B:B, 0) -> 324 | D6: =COUNTIFS(Results!J:J, A6, Results!B:B, 1) -> 305 | E6: =IF(C6=0, 0, D6/C6) -> 0.94135802 | F6: =COUNTIFS(Results!J:J, A6, Results!I:I, $F$1) -> 157 | G6: =COUNTIFS(Results!J:J, A6, Results!B:B, 1, Results!I:I, $F$1) + COUNTIFS(Results!J:J, A6, Results!B:B, 0, Results!I:I, $F$1) -> 157 | H6: =COUNTIFS(Results!I:I, $F$1,Results!J:J, A6, Results!B:B, 1) -> 156 | I6: =IFERROR(H6/G6, 0) -> 0.99363057 | J6: =COUNTIFS(Results!J:J, A6, Results!I:I, "casEN") + COUNTIFS(Results!J:J, A6, Results!I:I, "casEN_opti") -> 49 | K6: =COUNTIFS(Results!J:J, A6, Results!B:B, 1, Results!I:I, "casEN") + COUNTIFS(Results!J:J, A6, Results!B:B, 0, Results!I:I, "casEN") + COUNTIFS(Results!J:J, A6, Results!B:B, 1, Results!I:I, "casEN_opti") + COUNTIFS(Results!J:J, A6, Results!B:B, 0, Results!I:I, "casEN_opti") -> 49 | L6: =COUNTIFS(Results!I:I, "casEN",Results!J:J, A6, Results!B:B, 1) + COUNTIFS(Results!I:I, "casEN_opti",Results!J:J, A6, Results!B:B, 1) -> 37 | M6: =IFERROR(L6/K6, 0) -> 0.75510204 | N6: =(NER!$L$11+graphs_analyses!L6)/(graphs_analyses!K6 +NER!$K$11) - NER!$M$11 -> -0.0015229463 | R6: grfGeogPlaceGenerique | S6: grfgeogRiviere | T6: =COUNTIFS(Results!J:J, R6, Results!K:K, S6) -> 18 | U6: =COUNTIFS(Results!J:J, R6,Results!K:K, S6, Results!B:B, 1) + COUNTIFS(Results!J:J, R6,Results!K:K, S6, Results!B:B, 0) -> 11 | V6: =COUNTIFS(Results!J:J, R6, Results!K:K, S6, Results!B:B, 1) -> 11 | W6: =IFERROR(V6/U6, 0) -> 1 | X6: =COUNTIFS(Results!J:J, R6, Results!K:K, S6, Results!I:I, $X$1) -> 10 | Y6: =COUNTIFS(Results!J:J, R6,Results!K:K, S6, Results!I:I, $X$1, Results!B:B, 1) + COUNTIFS(Results!J:J, R6,Results!K:K, S6,Results!I:I, $X$1, Results!B:B, 0) -> 10 | Z6: =COUNTIFS(Results!J:J, R6, Results!K:K, S6, Results!I:I, $X$1, Results!B:B, 1) -> 10 | AA6: =IFERROR(Z6/Y6, 0) -> 1 | AB6: =COUNTIFS(Results!J:J, R6,Results!K:K, S6, Results!I:I, "casEN") + COUNTIFS(Results!J:J, R6,Results!K:K, S6, Results!I:I, "casEN_opti") -> 6 | AC6: =COUNTIFS(Results!J:J, R6,Results!K:K, S6, Results!B:B, 1, Results!I:I, "casEN") + COUNTIFS(Results!J:J, R6,Results!K:K, S6, Results!B:B, 0, Results!I:I, "casEN") + COUNTIFS(Results!J:J, R6,Results!K:K, S6, Results!B:B, 1, Results!I:I, "casEN_opti") + COUNTIFS(Results!J:J, R6,Results!K:K, S6, Results!B:B, 0, Results!I:I, "casEN_opti") -> 0 | AD6: =COUNTIFS(Results!J:J, R6,Results!K:K, S6, Results!B:B, 1, Results!I:I, "casEN") + COUNTIFS(Results!J:J, R6,Results!K:K, S6, Results!B:B, 1, Results!I:I, "casEN_opti") -> 0 | AE6: =IFERROR(AD6/AC6, 0) -> 0 | AF6: =(NER!$L$11+graphs_analyses!AD6)/(graphs_analyses!AC6 +NER!$K$11) - NER!$M$11 -> 0 | AJ6: grforgSeule | AK6: grforgProximite | AL6: grfpersPrenomNom | AM6: =COUNTIFS(Results!J:J, AJ6, Results!K:K, AK6, Results!L:L, AL6) -> 3 | AN6: =COUNTIFS(Results!J:J, AJ6, Results!K:K, AK6, Results!L:L, AL6, Results!B:B, 1) + COUNTIFS(Results!J:J, AJ6, Results!K:K, AK6, Results!L:L, AL6, Results!B:B, 0) -> 3 | AO6: =COUNTIFS(Results!J:J, AJ6, Results!K:K, AK6, Results!L:L, AL6, Results!B:B, 1) -> 1 | AP6: =IFERROR(AO6/AN6, 0) -> 0.33333333 | AQ6: =COUNTIFS(Results!J:J, AJ6, Results!K:K, AK6, Results!L:L, AL6, Results!I:I, $AQ$1) -> 0 | AR6: =COUNTIFS(Results!J:J, AJ6, Results!K:K, AK6, Results!L:L, AL6, Results!I:I, $AQ$1, Results!B:B, 1) + COUNTIFS(Results!J:J, AJ6, Results!K:K, AK6, Results!L:L, AL6, Results!I:I, $AQ$1, Results!B:B, 0) -> 0 | AS6: =COUNTIFS(Results!J:J, AJ6, Results!K:K, AK6, Results!L:L, AL6, Results!I:I, $AQ$1, Results!B:B, 1) -> 0 | AT6: =IFERROR(AS6/AR6, 0) -> 0 | AU6: =COUNTIFS(Results!J:J, AJ6,Results!K:K, AK6, Results!L:L, AL6,Results!I:I, "casEN") + COUNTIFS(Results!J:J, AJ6,Results!K:K, AK6, Results!L:L, AL6,Results!I:I, "casEN_opti") -> 3 | AV6: =COUNTIFS(Results!J:J, AJ6,Results!K:K, AK6, Results!L:L, AL6,Results!I:I, "casEN", Results!B:B, 1) + COUNTIFS(Results!J:J, AJ6,Results!K:K, AK6, Results!L:L, AL6,Results!I:I, "casEN", Results!B:B, 0) + COUNTIFS(Results!J:J, AJ6,Results!K:K, AK6, Results!L:L, AL6,Results!I:I, "casEN_opti", Results!B:B, 1) + COUNTIFS(Results!J:J, AJ6,Results!K:K, AK6, Results!L:L, AL6,Results!I:I, "casEN_opti", Results!B:B, 0) -> 3 | AW6: =COUNTIFS(Results!J:J, AJ6,Results!K:K, AK6, Results!L:L, AL6,Results!I:I, "casEN", Results!B:B, 1) + COUNTIFS(Results!J:J, AJ6,Results!K:K, AK6, Results!L:L, AL6,Results!I:I, "casEN_opti", Results!B:B, 1) -> 1 | AX6: =IFERROR(AW6/AV6, 0) -> 0.33333333 | AY6: =(NER!$L$11+graphs_analyses!AW6)/(graphs_analyses!AV6 +NER!$K$11) - NER!$M$11 -> -0.00027581211
A7: grfpersAmbigus | B7: =COUNTIF(Results!J:J, A7) -> 4 | C7: =COUNTIFS(Results!J:J, A7, Results!B:B, 1) + COUNTIFS(Results!J:J, A7, Results!B:B, 0) -> 4 | D7: =COUNTIFS(Results!J:J, A7, Results!B:B, 1) -> 4 | E7: =IF(C7=0, 0, D7/C7) -> 1 | F7: =COUNTIFS(Results!J:J, A7, Results!I:I, $F$1) -> 1 | G7: =COUNTIFS(Results!J:J, A7, Results!B:B, 1, Results!I:I, $F$1) + COUNTIFS(Results!J:J, A7, Results!B:B, 0, Results!I:I, $F$1) -> 1 | H7: =COUNTIFS(Results!I:I, $F$1,Results!J:J, A7, Results!B:B, 1) -> 1 | I7: =IFERROR(H7/G7, 0) -> 1 | J7: =COUNTIFS(Results!J:J, A7, Results!I:I, "casEN") + COUNTIFS(Results!J:J, A7, Results!I:I, "casEN_opti") -> 3 | K7: =COUNTIFS(Results!J:J, A7, Results!B:B, 1, Results!I:I, "casEN") + COUNTIFS(Results!J:J, A7, Results!B:B, 0, Results!I:I, "casEN") + COUNTIFS(Results!J:J, A7, Results!B:B, 1, Results!I:I, "casEN_opti") + COUNTIFS(Results!J:J, A7, Results!B:B, 0, Results!I:I, "casEN_opti") -> 3 | L7: =COUNTIFS(Results!I:I, "casEN",Results!J:J, A7, Results!B:B, 1) + COUNTIFS(Results!I:I, "casEN_opti",Results!J:J, A7, Results!B:B, 1) -> 3 | M7: =IFERROR(L7/K7, 0) -> 1 | N7: =(NER!$L$11+graphs_analyses!L7)/(graphs_analyses!K7 +NER!$K$11) - NER!$M$11 -> 1.1792147e-05 | R7: grfGeogPlaceGenerique | S7: grfgeogMer | T7: =COUNTIFS(Results!J:J, R7, Results!K:K, S7) -> 2 | U7: =COUNTIFS(Results!J:J, R7,Results!K:K, S7, Results!B:B, 1) + COUNTIFS(Results!J:J, R7,Results!K:K, S7, Results!B:B, 0) -> 0 | V7: =COUNTIFS(Results!J:J, R7, Results!K:K, S7, Results!B:B, 1) -> 0 | W7: =IFERROR(V7/U7, 0) -> 0 | X7: =COUNTIFS(Results!J:J, R7, Results!K:K, S7, Results!I:I, $X$1) -> 0 | Y7: =COUNTIFS(Results!J:J, R7,Results!K:K, S7, Results!I:I, $X$1, Results!B:B, 1) + COUNTIFS(Results!J:J, R7,Results!K:K, S7,Results!I:I, $X$1, Results!B:B, 0) -> 0 | Z7: =COUNTIFS(Results!J:J, R7, Results!K:K, S7, Results!I:I, $X$1, Results!B:B, 1) -> 0 | AA7: =IFERROR(Z7/Y7, 0) -> 0 | AB7: =COUNTIFS(Results!J:J, R7,Results!K:K, S7, Results!I:I, "casEN") + COUNTIFS(Results!J:J, R7,Results!K:K, S7, Results!I:I, "casEN_opti") -> 1 | AC7: =COUNTIFS(Results!J:J, R7,Results!K:K, S7, Results!B:B, 1, Results!I:I, "casEN") + COUNTIFS(Results!J:J, R7,Results!K:K, S7, Results!B:B, 0, Results!I:I, "casEN") + COUNTIFS(Results!J:J, R7,Results!K:K, S7, Results!B:B, 1, Results!I:I, "casEN_opti") + COUNTIFS(Results!J:J, R7,Results!K:K, S7, Results!B:B, 0, Results!I:I, "casEN_opti") -> 0 | AD7: =COUNTIFS(Results!J:J, R7,Results!K:K, S7, Results!B:B, 1, Results!I:I, "casEN") + COUNTIFS(Results!J:J, R7,Results!K:K, S7, Results!B:B, 1, Results!I:I, "casEN_opti") -> 0 | AE7: =IFERROR(AD7/AC7, 0) -> 0 | AF7: =(NER!$L$11+graphs_analyses!AD7)/(graphs_analyses!AC7 +NER!$K$11) - NER!$M$11 -> 0 | AJ7: grforgSeule | AK7: grforgPolice | AL7: grfpersPrenomNom | AM7: =COUNTIFS(Results!J:J, AJ7, Results!K:K, AK7, Results!L:L, AL7) -> 1 | AN7: =COUNTIFS(Results!J:J, AJ7, Results!K:K, AK7, Results!L:L, AL7, Results!B:B, 1) + COUNTIFS(Results!J:J, AJ7, Results!K:K, AK7, Results!L:L, AL7, Results!B:B, 0) -> 1 | AO7: =COUNTIFS(Results!J:J, AJ7, Results!K:K, AK7, Results!L:L, AL7, Results!B:B, 1) -> 0 | AP7: =IFERROR(AO7/AN7, 0) -> 0 | AQ7: =COUNTIFS(Results!J:J, AJ7, Results!K:K, AK7, Results!L:L, AL7, Results!I:I, $AQ$1) -> 0 | AR7: =COUNTIFS(Results!J:J, AJ7, Results!K:K, AK7, Results!L:L, AL7, Results!I:I, $AQ$1, Results!B:B, 1) + COUNTIFS(Results!J:J, AJ7, Results!K:K, AK7, Results!L:L, AL7, Results!I:I, $AQ$1, Results!B:B, 0) -> 0 | AS7: =COUNTIFS(Results!J:J, AJ7, Results!K:K, AK7, Results!L:L, AL7, Results!I:I, $AQ$1, Results!B:B, 1) -> 0 | AT7: =IFERROR(AS7/AR7, 0) -> 0 | AU7: =COUNTIFS(Results!J:J, AJ7,Results!K:K, AK7, Results!L:L, AL7,Results!I:I, "casEN") + COUNTIFS(Results!J:J, AJ7,Results!K:K, AK7, Results!L:L, AL7,Results!I:I, "casEN_opti") -> 1 | AV7: =COUNTIFS(Results!J:J, AJ7,Results!K:K, AK7, Results!L:L, AL7,Results!I:I, "casEN", Results!B:B, 1) + COUNTIFS(Results!J:J, AJ7,Results!K:K, AK7, Results!L:L, AL7,Results!I:I, "casEN", Results!B:B, 0) + COUNTIFS(Results!J:J, AJ7,Results!K:K, AK7, Results!L:L, AL7,Results!I:I, "casEN_opti", Results!B:B, 1) + COUNTIFS(Results!J:J, AJ7,Results!K:K, AK7, Results!L:L, AL7,Results!I:I, "casEN_opti", Results!B:B, 0) -> 1 | AW7: =COUNTIFS(Results!J:J, AJ7,Results!K:K, AK7, Results!L:L, AL7,Results!I:I, "casEN", Results!B:B, 1) + COUNTIFS(Results!J:J, AJ7,Results!K:K, AK7, Results!L:L, AL7,Results!I:I, "casEN_opti", Results!B:B, 1) -> 0 | AX7: =IFERROR(AW7/AV7, 0) -> 0 | AY7: =(NER!$L$11+graphs_analyses!AW7)/(graphs_analyses!AV7 +NER!$K$11) - NER!$M$11 -> -0.00013991165
