Workbook

Sheet Results
A1: manual cat | B1: correct | C1: extent | D1: category | E1: titles | F1: NER | G1: NER_label | H1: desc | I1: method | J1: main_graph | K1: second_graph | L1: third_graph | M1: file_id
E2: L'héritage | F2: Nathalie | G2: MISC | H2: le familiale depuis des générations.... Nathalie et Marianne aimeraient la vendre. Mais | I2: spaCy | M2: 0
A3: ERR | B3: 0 | C3: 0 | D3: ERR | E3: Money Flower | F3: A. Dans | G3: PER | H3: à la tête de la société Cheong A. Dans la lutte pour la succession du groupe, | I3: casEN | J3: grfpersPrenomNom | K3: grftagNomFamille | M3: 5268
A4: PER | B4: 1 | C4: 1 | D4: 1 | E4: Vampire Diaries (S4-E10) | F4: Aaron | G4: PER | H4: Elena se rend dans le dortoir d’Aaron, l’ancien colocataire de Jesse, afin qu’il l’aide à retrouver le docteur Maxfield et Damon. Il l’emmène dans la maison Whitmore, repaire des membres de la société Augustine. À leur arrivée, Wes injecte à la jeune fille une piqûre de verveine et l’enferme... avec son petit ami dans une cellule. Pendant ce temps, Caroline revient à Mystic Falls, déterminée à exorciser les démons de Stefan. | I4: intersection | J4: grfpersGenerique | M4: 253
E5: Bob l'éponge | F5: - Epidémie de hoquet | G5: LOC | H5: d'un nouvel ami adorable, mais collant. - Epidémie de hoquet . A Bikini Bottom, personne n'est à l'a | I5: spaCy | M5: 6625
A6: PER | B6: 0 | C6: 0 | D6: 1 | E6: L'héritage | F6: capitaine Dubreuil | G6: PER | H6: les rênes. Parallèlement, alors que le capitaine Dubreuil et son équipe piétinent dans leur enquê | I6: spaCy | M6: 0
E7: Phinéas et Ferb (S4-E22) | F7: - Recyclage | G7: LOC | H7: n de disparaître à la dernière seconde. - Recyclage d'inventions . Phineas, Ferb et leurs a | I7: spaCy | M7: 2790
E8: L'héritage | F8: Tessa | G8: MISC | H8: son équipe piétinent dans leur enquête, Tessa et ses sœurs entendent mener leurs prop | I8: spaCy | M8: 0
A9: ORG | B9: 0 | C9: 0 | D9: 1 | E9: Inazuma Eleven Go | F9: Académie | G9: ORG | H9: Le match contre la Royale Académie s'avère être très difficile. L'équipe est composée | I9: casEN | J9: grforgProximite | M9: 1564
A10: ERR | B10: 0 | C10: 0 | D10: ERR | E10: Money Flower | F10: A. Jalousé | G10: PER | H10: est directeur juridique du grand groupe Cheong A. Jalousé et envié, il est considéré comme le | I10: casEN | J10: grfpersPrenomNom | K10: grftagNomFamille | M10: 5268
E11: Phinéas et Ferb (S4-E22) | F11: - Retour | G11: LOC | H11: uve accidentellement changée en mouche. - Retour vers les années 50 . Phineas et Ferb re | I11: spaCy | M11: 2789
A12: PER | B12: 1 | C12: 1 | D12: 1 | E12: Vampire Diaries (S4-E10) | F12: Aaron | G12: PER | H12: chercher Stefan. Les deux frères partent questionner Aaron afin d'obtenir des informations sur le lieu | I12: intersection | J12: grfpersGenerique | M12: 254
A13: ORG | B13: 1 | C13: 1 | D13: 1 | E13: Nick Bollettieri, une vie de tennis | F13: académie | G13: ORG | H13: Inventeur du concept de l'académie géante de tennis, Nick Bollettieri a contribué à l'émergence de grands champions tels que André Agassi, Maria Sharapova, Monica Seles, ou encore Jim Courrier. Outre le portrait d'un des plus grands coachs du tennis moderne, ce film analyse les techniques... d'entraînements novatrices introduites par Bollettieri. | I13: casEN | J13: grforgProximite | M13: 1935
A14: PER | B14: 1 | C14: 1 | D14: 1 | E14: Somewhere Boy (S1-E1) | F14: Aaron | G14: PER | H14: Daisy invite Aaron et Danny à la fête agricole qu'elle | I14: intersection | J14: grfpersGenerique | M14: 1960
A15: PER | B15: 1 | C15: 1 | D15: 1 | E15: Somewhere Boy (S1-E1) | F15: Aaron | G15: PER | H15: Daisy invite Aaron et Danny à la fête agricole qu'elle | I15: intersection | J15: grfpersGenerique | M15: 1960
A16: PER | B16: 1 | C16: 1 | D16: 1 | E16: Somewhere Boy (S1-E1) | F16: Aaron | G16: PER | H16: Daisy invite Aaron et Danny à la fête agricole qu'elle | I16: intersection | J16: grfpersGenerique | M16: 1960
E17: 1, 2, 3 musette | F17: 123 Musette | G17: LOC | H17: 123 Musette - Spécial Grand Ouest | I17: spaCy | M17: 8352
E18: Himawari | F18: académie | G18: ORG | H18: Nouvelle à l'académie spécialisée dans la formation des femmes ninja, la jeune Himawari a juré fidélité et protection à celui qu'elle considère comme son mentor, un nouvel enseignant à qui un passé mystérieux la lie peut-être... Himawari va tout faire pour le protéger des embrouilles... causées par ses collègues et de la vie quotidienne à l'académie. | I18: casEN | J18: grforgProximite | M18: 5251
E19: Himawari | F19: académie | G19: ORG | H19: Nouvelle à l'académie spécialisée dans la formation des femmes ninja, la jeune Himawari a juré fidélité et protection à celui qu'elle considère comme son mentor, un nouvel enseignant à qui un passé mystérieux la lie peut-être... Himawari va tout faire pour le protéger des embrouilles... causées par ses collègues et de la vie quotidienne à l'académie. | I19: casEN | J19: grforgProximite | M19: 5251
E20: Himawari | F20: académie | G20: ORG | H20: Nouvelle à l'académie spécialisée dans la formation des femmes ninja, la jeune Himawari a juré fidélité et protection à celui qu'elle considère comme son mentor, un nouvel enseignant à qui un passé mystérieux la lie peut-être... Himawari va tout faire pour le protéger des embrouilles... causées par ses collègues et de la vie quotidienne à l'académie. | I20: casEN | J20: grforgProximite | M20: 5252
A21: PER | B21: 1 | C21: 1 | D21: 1 | E21: Somewhere Boy (S1-E1) | F21: Aaron | G21: PER | H21: Daisy invite Aaron et Danny à la fête agricole qu'elle | I21: intersection | J21: grfpersGenerique | M21: 1960
A22: PER | B22: 1 | C22: 1 | D22: 1 | E22: Somewhere Boy (S1-E1) | F22: Aaron | G22: PER | H22: Aaron est furieux contre Danny qui a gâché | I22: intersection | J22: grfpersGenerique | M22: 1961
A23: ERR | B23: 0 | C23: 0 | D23: ERR | E23: Wheeler Dealers France | F23: 231 ch | G23: LOC | H23: sur un modèle doté d'un V8 de 231 ch, mais malgré tout avec quelques défaillances mécaniques. | I23: casEN | J23: grfadress | K23: grftagAdresseRue | M23: 7296
E24: Ski alpin : Coupe du monde à Sölden | F24: 2e | G24: LOC | H24: Epreuve de Sölden. Slalom géant dames . 2e manche. | I24: spaCy | M24: 3115
A25: PER | B25: 1 | C25: 1 | D25: 1 | E25: Somewhere Boy (S1-E1) | F25: Aaron | G25: PER | H25: Aaron est furieux contre Danny qui a gâché | I25: intersection | J25: grfpersGenerique | M25: 1961
E26: Ski alpin : Coupe du monde à Sölden | F26: 2e | G26: LOC | H26: Epreuve de Sölden. Slalom géant dames . 2e manche. | I26: spaCy | M26: 3129
E27: Himawari | F27: académie | G27: ORG | H27: Nouvelle à l'académie spécialisée dans la formation des femmes ninja, la jeune Himawari a juré fidélité et protection à celui qu'elle considère comme son mentor, un nouvel enseignant à qui un passé mystérieux la lie peut-être... Himawari va tout faire pour le protéger des embrouilles... causées par ses collègues et de la vie quotidienne à l'académie. | I27: casEN | J27: grforgProximite | M27: 5252
E28: Yu-Gi-Oh ! GX | F28: Académie | G28: ORG | H28: L'année s'achève à la Duel Académie et les élèves vont bientôt connaître les | I28: casEN | J28: grforgProximite | M28: 5259
A29: PER | B29: 1 | C29: 1 | D29: 1 | E29: Ransom (S3-E1) | F29: Beaumont | G29: PER | H29: kidnappées. Lors de ses investigations, Beaumont découvre le milieu impitoyable du balle | I29: spaCy | M29: 8
A30: LOC | B30: 0 | C30: 0 | D30: 1 | E30: Envie dehors | F30: 3 Pays de la Loire | G30: LOC | H30: Production exécutive Nouveaux Jours productions France Télévisions - France 3 Pays de la Loire | I30: casEN | J30: grfadress | K30: grftagAdresseRue | M30: 4663
A31: PER | B31: 0 | C31: 0 | D31: 1 | E31: Comédie Club Tour : Kev Adams | F31: Adams | G31: PER | H31: Comedy Room, le 1er septembre 2020, Kev Adams, reçoit le Comédie Club tour où il | I31: casEN | J31: grfpersGenerique | M31: 2478
E32: Ransom (S3-E1) | F32: FBI | G32: ORG | H32: Le FBI est contraint de faire appel à Beaumont | I32: spaCy | M32: 9
E33: Pokémon : Diamant et perle | F33: académie | G33: ORG | H33: Bonville où habite Angie, de la Pokemon académie. La ville est terrorisée, car, le soir | I33: casEN | J33: grforgProximite | M33: 5983
E34: Orchestre de l'Opéra de Paris et Gustavo Dudamel : Concert inaugural | F34: Académie | G34: ORG | H34: Résumé Premier concert inaugural de Gustavo Duhamel à l'Opéra Garnier de Paris. Il dirige à cette occasion les artistes des Chœurs et de l’Académie ainsi que des solistes invités. De Carmen de Georges Bizet à Doctor Atomic de John Adams, de Lohengrin de Richard Wagner à Ainadamar de Osvaldo... Golijov, du Chevalier à la rose de Richard Strauss à Falstaff de Giuseppe Verdi, de La Vida breve de Manuel De Falla à Peter Grimes de Benjamin Britten, les plus grands morceaux mythiques (duo, ballets, ballets, ensembles ou encore interludes) sont interprétés. Voirplusmoins | I34: casEN | J34: grforgProximite | M34: 6271
A35: PER | B35: 1 | C35: 1 | D35: 1 | E35: Somewhere Boy (S1-E1) | F35: Aaron | G35: PER | H35: Aaron est furieux contre Danny qui a gâché | I35: intersection | J35: grfpersGenerique | M35: 1961
A36: PER | B36: 1 | C36: 1 | D36: 1 | E36: Somewhere Boy (S1-E1) | F36: Aaron | G36: PER | H36: Aaron est furieux contre Danny qui a gâché | I36: intersection | J36: grfpersGenerique | M36: 1961
E37: Révélations monumentales | F37: 3D | G37: LOC | H37: e. Du drone technique aux relevés laser 3D, le monument est ausculté par les scien | I37: spaCy | M37: 5342
A38: PER | B38: 1 | C38: 1 | D38: 1 | E38: Chicago Police Department (S2-E10) | F38: Erin | G38: PER | H38: tente de le faire parler. De son côté, Erin a du mal à reprendre le dessus et doit | I38: spaCy | M38: 13
E39: Yu-Gi-Oh ! GX | F39: Académie des Duellistes fondée | G39: ORG | H39: Yu-Gi-Oh-! GX se déroule des années après l'histoire de Yugi Mûto. On y découvre Juudai Yuuki dans le rôle du héros. Ce dernier va à l'Académie des Duellistes fondée par Seto KaÔba pour y être admis. Il croise en route un personnage dont la coupe de cheveux rappelle Yugi Mûto et reçoit... une carte qui l'accompagnera durant son aventure. Yuuki est admis et, dès lors, son avenir sera truffé de combats toujours plus difficiles les uns que les autres. | I39: casEN | J39: grforgEconomie | M39: 5265
A40: PER | B40: 1 | C40: 1 | D40: 1 | E40: Chicago Police Department (S2-E10) | F40: Voight | G40: PER | H40: e affaire sur laquelle elle intervient. Voight parvient à neutraliser l'un... des malf | I40: spaCy | M40: 13
...

Sheet Analyses
A1: {=_xlfn.UNIQUE(_xlfn._xlws.FILTER(Results!I:I, Results!I:I <> ""))} -> method | B1: Total Found | C1: (corrected lines) | D1: Total Correct | E1: Accuracy
A2: spaCy | B2: =COUNTIF(Results!I:I, A2) -> 15127 | C2: =COUNTIFS(Results!I:I, A2, Results!B:B, 1) + COUNTIFS(Results!I:I, A2, Results!B:B, 0) -> 17 | D2: =COUNTIFS(Results!I:I, A2, Results!B:B, 1) -> 14 | E2: =IFERROR(D2/C2, 0) -> 0.82352941
A3: casEN | B3: =COUNTIF(Results!I:I, A3) -> 7536 | C3: =COUNTIFS(Results!I:I, A3, Results!B:B, 1) + COUNTIFS(Results!I:I, A3, Results!B:B, 0) -> 1359 | D3: =COUNTIFS(Results!I:I, A3, Results!B:B, 1) -> 727 | E3: =IFERROR(D3/C3, 0) -> 0.53495217
A4: intersection | B4: =COUNTIF(Results!I:I, A4) -> 7548 | C4: =COUNTIFS(Results!I:I, A4, Results!B:B, 1) + COUNTIFS(Results!I:I, A4, Results!B:B, 0) -> 7524 | D4: =COUNTIFS(Results!I:I, A4, Results!B:B, 1) -> 6920 | E4: =IFERROR(D4/C4, 0) -> 0.91972355
B9: NER system | D9: lines | E9: total errors | F9: extent correct | G9: category correct | H9: extent+catégory correct | I9: erreur | J9: precision extent but some incorrect categories | K9: precision categorized | L9: precision extent+categorized | M9: it is a PER but not well tagged by system | N9: it is a LOC but not well tagged by system | O9: it is a ORG but not well tagged by system | P9: category PER error among NE found by system | Q9: category LOC error among NE found by system | R9: category ORG error among NE found by system | S9: estimated recall : good entities found by a system / all good entities
A10: intersection spacy/CasEN | B10: intersection | C10: NE | D10: =COUNTIFS(Results!I:I, B10) -> 7548 | E10: =COUNTIFS(Results!I:I, B11, Results!B:B, 0) -> 604 | F10: =COUNTIFS(Results!I:I, B10, Results!C:C, 1) -> 6984 | G10: =COUNTIFS(Results!I:I, B10, Results!D:D, 1) -> 7364 | H10: =COUNTIFS(Results!I:I, B10, Results!B:B, 1) -> 6920 | I10: =IFERROR(E10/D10, 0) -> 0.080021198 | J10: =IFERROR(F10/$D$10, 0) -> 0.92527822 | K10: =IFERROR(G10/$D$10, 0) -> 0.97562268 | L10: =IFERROR(H10/$D$10, 0) -> 0.91679915 | M10: =SUM(M11:M14) -> 10 | N10: =SUM(N11:N14) -> 3 | O10: =SUM(O11:O14) -> 19 | P10: =IFERROR(M10/F10, 0) -> 0.0014318442 | Q10: =IFERROR(N10/G10, 0) -> 0.00040738729 | R10: =IFERROR(O10/H10, 0) -> 0.0027456647
B11: intersection | C11: PER | D11: =COUNTIFS(Results!G:G, C11, Results!I:I, B11) -> 6091 | E11: =COUNTIFS(Results!G:G, C11, Results!I:I, B11, Results!B:B, 0) -> 513 | F11: =COUNTIFS(Results!G:G, C11, Results!I:I, B11, Results!C:C, 1) -> 5604 | G11: =COUNTIFS(Results!G:G, C11, Results!I:I, B11, Results!D:D, 1) -> 5973 | H11: =COUNTIFS(Results!G:G, C11, Results!I:I, B11, Results!B:B, 1) -> 5565 | I11: =IFERROR(E11/D11, 0) -> 0.084222624 | J11: =IFERROR(F11/$D$11, 0) -> 0.92004597 | K11: =IFERROR(G11/$D$11, 0) -> 0.98062715 | L11: =IFERROR(H11/$D$11, 0) -> 0.91364308 | M11: 0 | N11: =COUNTIFS(Results!I:I,$B$11,Results!G:G,$C$11,Results!C:C, 1, Results!A:A,"LOC") -> 3 | O11: =COUNTIFS(Results!I:I,$B$11,Results!G:G,$C$11,Results!C:C, 1, Results!A:A,"ORG") -> 6 | P11: =IFERROR(M11/F11, 0) -> 0 | Q11: =IFERROR(N11/G11, 0) -> 0.00050226017 | R11: =IFERROR(O11/H11, 0) -> 0.0010781671
B12: intersection | C12: LOC | D12: =COUNTIFS(Results!G:G, C12, Results!I:I, B12) -> 1296 | E12: =COUNTIFS(Results!G:G, C12, Results!I:I, B12, Results!B:B, 0) -> 74 | F12: =COUNTIFS(Results!G:G, C12, Results!I:I, B12, Results!C:C, 1) -> 1238 | G12: =COUNTIFS(Results!G:G, C12, Results!I:I, B12, Results!D:D, 1) -> 1253 | H12: =COUNTIFS(Results!G:G, C12, Results!I:I, B12, Results!B:B, 1) -> 1217 | I12: =IFERROR(E12/D12, 0) -> 0.057098765 | J12: =IFERROR(F12/$D$12, 0) -> 0.95524691 | K12: =IFERROR(G12/$D$12, 0) -> 0.96682099 | L12: =IFERROR(H12/$D$12, 0) -> 0.93904321 | M12: =COUNTIFS(Results!$I:$I,$B$12,Results!$G:$G,$C$12,Results!$C:$C, 1, Results!$A:$A,"PER") -> 6 | N12: 0 | O12: =COUNTIFS(Results!$I:$I,$B$12,Results!$G:$G,$C$12,Results!$C:$C, 1, Results!$A:$A,"ORG") -> 13 | P12: =IFERROR(M12/F12, 0) -> 0.0048465267 | Q12: =IFERROR(N12/G12, 0) -> 0 | R12: =IFERROR(O12/H12, 0) -> 0.010682005
B13: intersection | C13: ORG | D13: =COUNTIFS(Results!G:G, C13, Results!I:I, B13) -> 161 | E13: =COUNTIFS(Results!G:G, C13, Results!I:I, B13, Results!B:B, 0) -> 17 | F13: =COUNTIFS(Results!G:G, C13, Results!I:I, B13, Results!C:C, 1) -> 142 | G13: =COUNTIFS(Results!G:G, C13, Results!I:I, B13, Results!D:D, 1) -> 138 | H13: =COUNTIFS(Results!G:G, C13, Results!I:I, B13, Results!B:B, 1) -> 138 | I13: =IFERROR(E13/D13, 0) -> 0.10559006 | J13: =IFERROR(F13/$D$13, 0) -> 0.88198758 | K13: =IFERROR(G13/$D$13, 0) -> 0.85714286 | L13: =IFERROR(H13/$D$13, 0) -> 0.85714286 | M13: =COUNTIFS(Results!$I:$I,$B$13,Results!$G:$G,$C$13,Results!$C:$C, 1, Results!$A:$A,"PER") -> 4 | N13: =COUNTIFS(Results!$I:$I,$B$13,Results!$G:$G,$C$13,Results!$C:$C, 1, Results!$A:$A,"LOC") -> 0 | O13: 0 | P13: =IFERROR(M13/F13, 0) -> 0.028169014 | Q13: =IFERROR(N13/G13, 0) -> 0 | R13: =IFERROR(O13/H13, 0) -> 0
B14: intersection | C14: MISC | D14: =COUNTIFS(Results!G:G, C14, Results!I:I, B14) -> 0 | E14: =COUNTIFS(Results!G:G, C14, Results!I:I, B14, Results!B:B, 0) -> 0 | F14: =COUNTIFS(Results!G:G, C14, Results!I:I, B14, Results!C:C, 1) -> 0 | G14: =COUNTIFS(Results!G:G, C14, Results!I:I, B14, Results!D:D, 1) -> 0 | H14: =COUNTIFS(Results!G:G, C14, Results!I:I, B14, Results!B:B, 1) -> 0 | I14: =IFERROR(E14/D14, 0) -> 0 | J14: =IFERROR(F14/$D$14, 0) -> 0 | K14: =IFERROR(G14/$D$14, 0) -> 0 | L14: =IFERROR(H14/$D$14, 0) -> 0 | M14: =COUNTIFS(Results!$I:$I,B14,Results!$G:$G,C14,Results!$C:$C, 1, Results!$A:$A,"PER") -> 0 | N14: 0 | O14: 0 | P14: =IFERROR(M14/F14, 0) -> 0 | Q14: =IFERROR(N14/G14, 0) -> 0 | R14: =IFERROR(O14/H14, 0) -> 0
A18: NE only found by casEN (without intersection) | B18: casEN | C18: NE | D18: =COUNTIFS(Results!I:I, B18) -> 7536 | E18: =COUNTIFS(Results!I:I, B19, Results!B:B, 0) -> 632 | F18: =COUNTIFS(Results!I:I, B18, Results!C:C, 1) -> 770 | G18: =COUNTIFS(Results!I:I, B18, Results!D:D, 1) -> 817 | H18: =COUNTIFS(Results!I:I, B18, Results!B:B, 1) -> 727 | I18: =IFERROR(E18/D18, 0) -> 0.083864119 | J18: =IFERROR(F18/$D$18, 0) -> 0.10217622 | K18: =IFERROR(G18/$D$18, 0) -> 0.10841295 | L18: =IFERROR(H18/$D$18, 0) -> 0.096470276 | M18: =SUM(M19:M22) -> 8 | N18: =SUM(N19:N22) -> 16 | O18: =SUM(O19:O22) -> 17 | P18: =IFERROR(M18/F18, 0) -> 0.01038961 | Q18: =IFERROR(N18/G18, 0) -> 0.019583843 | R18: =IFERROR(O18/H18, 0) -> 0.023383769
B19: casEN | C19: PER | D19: =COUNTIFS(Results!G:G, C19, Results!I:I, B19) -> 4202 | E19: =COUNTIFS(Results!G:G, C19, Results!I:I, B19, Results!B:B, 0) -> 119 | F19: =COUNTIFS(Results!G:G, C19, Results!I:I, B19, Results!C:C, 1) -> 338 | G19: =COUNTIFS(Results!G:G, C19, Results!I:I, B19, Results!D:D, 1) -> 334 | H19: =COUNTIFS(Results!G:G, C19, Results!I:I, B19, Results!B:B, 1) -> 315 | I19: =IFERROR(E19/$D$19, 0) -> 0.028319848 | J19: =IFERROR(F19/$D$19, 0) -> 0.080437887 | K19: =IFERROR(G19/$D$19, 0) -> 0.079485959 | L19: =IFERROR(H19/$D$19, 0) -> 0.074964303 | M19: 0 | N19: =COUNTIFS(Results!I:I,$B$19,Results!G:G,$C$19,Results!C:C, 1, Results!A:A,"LOC") -> 16 | O19: =COUNTIFS(Results!I:I,$B$19,Results!G:G,$C$19,Results!C:C, 1, Results!A:A,"ORG") -> 5 | P19: =IFERROR(M19/F19, 0) -> 0 | Q19: =IFERROR(N19/G19, 0) -> 0.047904192 | R19: =IFERROR(O19/H19, 0) -> 0.015873016
B20: casEN | C20: LOC | D20: =COUNTIFS(Results!G:G, C20, Results!I:I, B20) -> 925 | E20: =COUNTIFS(Results!G:G, C20, Results!I:I, B20, Results!B:B, 0) -> 511 | F20: =COUNTIFS(Results!G:G, C20, Results!I:I, B20, Results!C:C, 1) -> 430 | G20: =COUNTIFS(Results!G:G, C20, Results!I:I, B20, Results!D:D, 1) -> 480 | H20: =COUNTIFS(Results!G:G, C20, Results!I:I, B20, Results!B:B, 1) -> 410 | I20: =IFERROR(E20/$D$20, 0) -> 0.55243243 | J20: =IFERROR(F20/$D$20, 0) -> 0.46486486 | K20: =IFERROR(G20/$D$20, 0) -> 0.51891892 | L20: =IFERROR(H20/$D$20, 0) -> 0.44324324 | M20: =COUNTIFS(Results!I:I,$B$20,Results!G:G,$C$20,Results!C:C, 1, Results!A:A,"PER") -> 8 | N20: 0 | O20: =COUNTIFS(Results!I:I,$B$20,Results!G:G,$C$20,Results!C:C, 1, Results!A:A,"ORG") -> 12 | P20: =IFERROR(M20/F20, 0) -> 0.018604651 | Q20: =IFERROR(N20/G20, 0) -> 0 | R20: =IFERROR(O20/H20, 0) -> 0.029268293
B21: casEN | C21: ORG | D21: =COUNTIFS(Results!G:G, C21, Results!I:I, B21) -> 2409 | E21: =COUNTIFS(Results!G:G, C21, Results!I:I, B21, Results!B:B, 0) -> 2 | F21: =COUNTIFS(Results!G:G, C21, Results!I:I, B21, Results!C:C, 1) -> 2 | G21: =COUNTIFS(Results!G:G, C21, Results!I:I, B21, Results!D:D, 1) -> 3 | H21: =COUNTIFS(Results!G:G, C21, Results!I:I, B21, Results!B:B, 1) -> 2 | I21: =IFERROR(E21/$D$21, 0) -> 0.00083022001 | J21: =IFERROR(F21/$D$21, 0) -> 0.00083022001 | K21: =IFERROR(G21/$D$21, 0) -> 0.00124533 | L21: =IFERROR(H21/$D$21, 0) -> 0.00083022001 | M21: =COUNTIFS(Results!I:I,$B$21,Results!G:G,$C$21,Results!C:C, 1, Results!A:A,"PER") -> 0 | N21: =COUNTIFS(Results!I:I,$B$21,Results!G:G,$C$21,Results!C:C, 1, Results!A:A,"LOC") -> 0 | O21: 0 | P21: =IFERROR(M21/F21, 0) -> 0 | Q21: =IFERROR(N21/G21, 0) -> 0 | R21: =IFERROR(O21/H21, 0) -> 0
B22: casEN | C22: MISC | D22: =COUNTIFS(Results!G:G, C22, Results!I:I, B22) -> 0 | E22: =COUNTIFS(Results!G:G, C22, Results!I:I, B22, Results!B:B, 0) -> 0 | F22: =COUNTIFS(Results!G:G, C22, Results!I:I, B22, Results!C:C, 1) -> 0 | G22: =COUNTIFS(Results!G:G, C22, Results!I:I, B22, Results!D:D, 1) -> 0 | H22: =COUNTIFS(Results!G:G, C22, Results!I:I, B22, Results!B:B, 1) -> 0 | I22: =IFERROR(E22/$D$22, 0) -> 0 | J22: =IFERROR(F22/$D$22, 0) -> 0 | K22: =IFERROR(G22/$D$22, 0) -> 0 | L22: =IFERROR(H22/$D$22, 0) -> 0 | M22: 0 | N22: 0 | O22: 0 | P22: =IFERROR(M22/F22, 0) -> 0 | Q22: =IFERROR(N22/G22, 0) -> 0 | R22: =IFERROR(O22/H22, 0) -> 0
A26: NE only found by spaCy (without intersection) | B26: spaCy | C26: NE | D26: =COUNTIFS(Results!I:I, B26) -> 15127 | E26: =COUNTIFS(Results!I:I, B27, Results!B:B, 0) -> 3 | F26: =COUNTIFS(Results!I:I, B26, Results!C:C, 1) -> 14 | G26: =COUNTIFS(Results!I:I, B26, Results!D:D, 1) -> 15 | H26: =COUNTIFS(Results!I:I, B26, Results!B:B, 1) -> 14 | I26: =IFERROR(E26/$D$26, 0) -> 0.00019832088 | J26: =IFERROR(F26/$D$26, 0) -> 0.00092549745 | K26: =IFERROR(G26/$D$26, 0) -> 0.00099160442 | L26: =IFERROR(H26/$D$26, 0) -> 0.00092549745 | M26: =SUM(M27:M30) -> 0 | N26: =SUM(N27:N30) -> 0 | O26: =SUM(O27:O30) -> 0 | P26: =IFERROR(M26/F26, 0) -> 0 | Q26: =IFERROR(N26/G26, 0) -> 0 | R26: =IFERROR(O26/H26, 0) -> 0
B27: spaCy | C27: PER | D27: =COUNTIFS(Results!G:G, C27, Results!I:I, B27) -> 4413 | E27: =COUNTIFS(Results!G:G, C27, Results!I:I, B27, Results!B:B, 0) -> 2 | F27: =COUNTIFS(Results!G:G, C27, Results!I:I, B27, Results!C:C, 1) -> 14 | G27: =COUNTIFS(Results!G:G, C27, Results!I:I, B27, Results!D:D, 1) -> 15 | H27: =COUNTIFS(Results!G:G, C27, Results!I:I, B27, Results!B:B, 1) -> 14 | I27: =IFERROR(E27/$D$27, 0) -> 0.00045320644 | J27: =IFERROR(F27/$D$27, 0) -> 0.003172445 | K27: =IFERROR(G27/$D$27, 0) -> 0.0033990483 | L27: =IFERROR(H27/$D$27, 0) -> 0.003172445 | M27: 0 | N27: =COUNTIFS(Results!I:I,B27,Results!G:G,C27,Results!C:C, 1, Results!A:A,"LOC") -> 0 | O27: =COUNTIFS(Results!I:I,B27,Results!G:G,C27,Results!C:C, 1, Results!A:A,"ORG") -> 0 | P27: =IFERROR(M27/F27, 0) -> 0 | Q27: =IFERROR(N27/G27, 0) -> 0 | R27: =IFERROR(O27/H27, 0) -> 0
B28: spaCy | C28: LOC | D28: =COUNTIFS(Results!G:G, C28, Results!I:I, B28) -> 5476 | E28: =COUNTIFS(Results!G:G, C28, Results!I:I, B28, Results!B:B, 0) -> 1 | F28: =COUNTIFS(Results!G:G, C28, Results!I:I, B28, Results!C:C, 1) -> 0 | G28: =COUNTIFS(Results!G:G, C28, Results!I:I, B28, Results!D:D, 1) -> 0 | H28: =COUNTIFS(Results!G:G, C28, Results!I:I, B28, Results!B:B, 1) -> 0 | I28: =IFERROR(E28/$D$28, 0) -> 0.00018261505 | J28: =IFERROR(F28/$D$28, 0) -> 0 | K28: =IFERROR(G28/$D$28, 0) -> 0 | L28: =IFERROR(H28/$D$28, 0) -> 0 | M28: =COUNTIFS(Results!I:I,$B$28,Results!G:G,$C$28,Results!C:C, 1, Results!A:A,"PER") -> 0 | N28: 0 | O28: =COUNTIFS(Results!I:I,B28,Results!G:G,C28,Results!C:C, 1, Results!A:A,"ORG") -> 0 | P28: =IFERROR(M28/F28, 0) -> 0 | Q28: =IFERROR(N28/G28, 0) -> 0 | R28: =IFERROR(O28/H28, 0) -> 0
B29: spaCy | C29: ORG | D29: =COUNTIFS(Results!G:G, C29, Results!I:I, B29) -> 921 | E29: =COUNTIFS(Results!G:G, C29, Results!I:I, B29, Results!B:B, 0) -> 0 | F29: =COUNTIFS(Results!G:G, C29, Results!I:I, B29, Results!C:C, 1) -> 0 | G29: =COUNTIFS(Results!G:G, C29, Results!I:I, B29, Results!D:D, 1) -> 0 | H29: =COUNTIFS(Results!G:G, C29, Results!I:I, B29, Results!B:B, 1) -> 0 | I29: =IFERROR(E29/$D$29, 0) -> 0 | J29: =IFERROR(F29/$D$29, 0) -> 0 | K29: =IFERROR(G29/$D$29, 0) -> 0 | L29: =IFERROR(H29/$D$29, 0) -> 0 | M29: =COUNTIFS(Results!I:I,$B$29,Results!G:G,$C$29,Results!C:C, 1, Results!A:A,"PER") -> 0 | N29: =COUNTIFS(Results!I:I,B29,Results!G:G,C29,Results!C:C, 1, Results!A:A,"LOC") -> 0 | O29: 0 | P29: =IFERROR(M29/F29, 0) -> 0 | Q29: =IFERROR(N29/G29, 0) -> 0 | R29: =IFERROR(O29/H29, 0) -> 0
B30: spaCy | C30: MISC | D30: =COUNTIFS(Results!G:G, C30, Results!I:I, B30) -> 4317 | E30: =COUNTIFS(Results!G:G, C30, Results!I:I, B30, Results!B:B, 0) -> 0 | F30: =COUNTIFS(Results!G:G, C30, Results!I:I, B30, Results!C:C, 1) -> 0 | G30: =COUNTIFS(Results!G:G, C30, Results!I:I, B30, Results!D:D, 1) -> 0 | H30: =COUNTIFS(Results!G:G, C30, Results!I:I, B30, Results!B:B, 1) -> 0 | I30: =IFERROR(E30/$D$30, 0) -> 0 | J30: =IFERROR(F30/$D$30, 0) -> 0 | K30: =IFERROR(G30/$D$30, 0) -> 0 | L30: =IFERROR(H30/$D$30, 0) -> 0 | M30: =COUNTIFS(Results!I:I,$B$30,Results!G:G,$C$30,Results!C:C, 1, Results!A:A,"PER") -> 0 | N30: =COUNTIFS(Results!I:I,B30,Results!G:G,C30,Results!C:C, 1, Results!A:A,"LOC") -> 0 | O30: =COUNTIFS(Results!I:I,B30,Results!G:G,C30,Results!C:C, 1, Results!A:A,"ORG") -> 0 | P30: =IFERROR(M30/F30, 0) -> 0 | Q30: =IFERROR(N30/G30, 0) -> 0 | R30: =IFERROR(O30/H30, 0) -> 0
